Workbook

Sheet ▶️ Инструкция
B2: ИНСТРУКЦИЯ ПО НАСТРОЙКЕ КАЛЬКУЛЯТОРА:
I5: 01.1 | Z5: 01.2 | AQ5: 01.3
E6: Жмем «Файл» → «Создать копию» → Вводим свое название → «Копировать» | T6: Вручную обновите данные во вкладке «📄Комиссии» в ячейках ниже 6-ой строки на актуальные из личного кабинета селлера по ссылке | AM6: Вручную обновите данные во вкладке «🔒Доп. информация» в ячейках I9:N10 и C12:F100 на актуальные из личного кабинета селлера по ссылке
D13: 02 | G13: 03 | N13: 04 | R13: 05 | U13: 06 | Y13: 07 | AD13: 08 | AI13: 09
C14: Названия ваших ИП | G14: Что для нас важно — маржинальность от пришедших денег на счет или маржинальность от цены продажи? | N14: Маржинальность в процентах, ниже которой нам не интересно работать | R14: Налог УСН «Доходы» + страховые | Y14: Выбираем, как считать налог — с продаж (это правильно) или с денег, пришедших на счет | AD14: Налог НДС | AI14: Выбираем процент эквайринга на WB. Может быть от 0,4% до 3,0%
C16: ИП Копытина К.В. | G16: Маржинальность прихода | N16: 0.15 | R16: 0.07 | Y16: Налог с продаж | AD16: 0 | AI16: 0.03
C17: ип Samga | G17: Маржинальность прихода | N17: 0.1 | R17: 0.04 | Y17: Налог с продаж | AD17: 0 | AI17: 0.02
C18: ип F | G18: Маржинальность прихода | N18: 0.05 | R18: 0.04 | Y18: Налог с продаж | AD18: 0 | AI18: 0.02
C19: ИП Кузнецов И.И.
M22: 12 | AA22: 13 | AQ22: 14
I23: В «🤖 Калькулятор» в столбце AP выбираем ваше ИП | T23: В «🤖 Калькулятор» в столбце AQ выбираем название маркетплейса, для которого делаем расчет | AK23: В «🤖 Калькулятор» в столбце AR выбираем FBO или FBS
R30: 15
R31: Чтобы верно посчитать Unit-экономику WB, нужно использовать коэффициенты самого дорого нашего склада.
R34: Вписываем, на какие склады WB мы готовы грузиться или уже грузимся
S36: Коледино, Электросталь, Краснодар (Тихорецкая), Казань, Санкт-Петербург (Уткина Заводь), СЦ Хабаровск, Тула
R41: 16
P42: Выбор опций для ваших ИП из Конструктора тарифов на WB
R45: Выбираем ИП из вашего списка в пункте 02:
R46: ИП Копытина К.В. | AG46: Суммарный %: | AK46: =IFERROR(__xludf.DUMMYFUNCTION("SUM(ArrayFormula(SUMIF('🔒 Доп. информация'!J:J,TRANSPOSE(SPLIT(Q48,"", "",FALSE,TRUE)),'🔒 Доп. информация'!P:P)))"),0.0) -> 0
Q47: Выбираем опции тарифа:
R53: Выбираем ИП из вашего списка в пункте 02:
R54: ИП Кузнецов И.И. | AG54: Суммарный %: | AK54: =IFERROR(__xludf.DUMMYFUNCTION("SUM(ArrayFormula(SUMIF('🔒 Доп. информация'!J:J,TRANSPOSE(SPLIT(Q56,"", "",FALSE,TRUE)),'🔒 Доп. информация'!P:P)))"),0.0) -> 0
Q55: Выбираем опции тарифа:
R61: Выбираем ИП из вашего списка в пункте 02:
R62: 2 Бренд | AG62: Суммарный %: | AK62: =IFERROR(__xludf.DUMMYFUNCTION("SUM(ArrayFormula(SUMIF('🔒 Доп. информация'!J:J,TRANSPOSE(SPLIT(Q64,"", "",FALSE,TRUE)),'🔒 Доп. информация'!P:P)))"),0.0) -> 0
Q63: Выбираем опции тарифа:
R69: Выбираем ИП из вашего списка в пункте 02:
AG70: Суммарный %: | AK70: =IFERROR(__xludf.DUMMYFUNCTION("SUM(ArrayFormula(SUMIF('🔒 Доп. информация'!J:J,TRANSPOSE(SPLIT(Q72,"", "",FALSE,TRUE)),'🔒 Доп. информация'!P:P)))"),0.0) -> 0
Q71: Выбираем опции тарифа:
R77: Выбираем ИП из вашего списка в пункте 02:
AG78: Суммарный %: | AK78: =IFERROR(__xludf.DUMMYFUNCTION("SUM(ArrayFormula(SUMIF('🔒 Доп. информация'!J:J,TRANSPOSE(SPLIT(Q80,"", "",FALSE,TRUE)),'🔒 Доп. информация'!P:P)))"),0.0) -> 0
Q79: Выбираем опции тарифа:
R85: Выбираем ИП из вашего списка в пункте 02:
AG86: Суммарный %: | AK86: =IFERROR(__xludf.DUMMYFUNCTION("SUM(ArrayFormula(SUMIF('🔒 Доп. информация'!J:J,TRANSPOSE(SPLIT(Q88,"", "",FALSE,TRUE)),'🔒 Доп. информация'!P:P)))"),0.0) -> 0
Q87: Выбираем опции тарифа:
A93: ОПИСАНИЕ ВКЛАДОК:
M95: 01 | AE95: 02
M96: В 5 строчке в «🤖Калькулятор» указаны объяснения значений каждого столбца калькулятора. Их можно скрыть или открыть, нажав на ➕слева от строки 4 | AE96: Во вкладке «📄Комиссии» — актуальные комиссии всех марктелпейсов. Эти данные периодически меняются, ссылки на актуальные данные указаны в таблице
M103: 03
M104: Во вкладке «🔒Доп. информация» указаны актуальные дополнительные данные от марктеплейсов. Эти данные периодически меняются, ссылки на актуальные данные указаны в таблице

Sheet 🤖 Калькулятор
G1: ✏️ ЗАПОЛНИТЬ | AT1: 💼 УСЛОВИЯ | AW1: 📈 ЭФФЕКТИВНОСТЬ ПРОДАЖИ | BJ1: 🧮 РАСЧЁТЫ
G2: ⬇️ | H2: ⬇️ | I2: ⬇️ | J2: ⬇️ | K2: 💰 | L2: ⬇️ | M2: ⬇️ | N2: 🔒 | O2: 💰 | Q2: 💰 | S2: ⬇️ | T2: ⬇️ | U2: ⬇️ | V2: 💰 | W2: 💰 | X2: 💰 | Y2: 💰 | Z2: ⬇️ | AA2: 🔒 | AB2: 💰 | AC2: 💰 | AD2: 💰 | AE2: ⬇️ | AF2: ⬇️ | AG2: ⬇️ | AH2: ⬇️ | AI2: 🔒 | AJ2: 🔒 | AK2: 💰 | AL2: 🔒 | AM2: 💰 | AN2: ⬇️ | AO2: ⬇️ | AP2: ⬇️ | AQ2: ⬇️ | AR2: ⬇️ | AS2: ⬇️ | AW2: 🔒 | AX2: 🔒 | AY2: 🔒 | AZ2: ⬇️ | BA2: 🔒 | BB2: 🔒 | BC2: 🔒 | BD2: 🔒 | BE2: 🔒 | BF2: 🔒 | BG2: 🔒 | BH2: 🔒
A3: ✅/❌ | B3: FBS/ FBO | C3: SKU | D3: Вкл. строку | E3: Менеджер | F3: Вывод | G3: Закупка, 1 шт | H3: Продажа, 1 шт | I3: Предпола- гаемый СПП + Кошелек WB | J3: Кешбек WB | K3: Сколько % комиссии снижает акция OZON | L3: Сколько штук в партии? | M3: Комиссия маркетплейса | S3: Куда и как отгружаем WB? | U3: ИЛ WB | V3: Индекс лока- лизации OZON | W3: Обработка товара в составе грузоместа OZON | Y3: Доля локаль- ных продаж Я.Маркет | Z3: Коэфф приемки WB | AA3: Приемка WB | AB3: Передал до рекомендованного слота отгрузки OZON | AC3: Приемка OZON | AD3: Приемка Я.Маркет | AE3: Дней на продажу партии FBW | AF3: Высота Ширина Длина в !СМ! | AI3: Объем/ объем. вес | AJ3: Доп. объем | AK3: Вес, кг Я.Маркет | AL3: Эквай- ринг WB | AM3: Перевод платежей Я.Маркет | AN3: Цена отгруз-ки еди- ницы на FBO | AO3: Цена отгруз-ки еди- ницы на FBS | AP3: Доп. затра- ты на еди- ницу | AQ3: % выкупа | AR3: % брака | AS3: % на марке- тинг | AT3: ИП | AU3: Площадка | AV3: Направ- ление | AW3: CPO Цена заказа | AX3: CPS Цена продажи | AY3: Процент рекламы в ЧП | AZ3: CPO (задаем) | BA3: ДРР из CPO | BB3: ЦЕНА- CPO | BC3: ЧП 1 шт. | BD3: ЧП партии | BE3: Выручка партии | BF3: Рентабель- ность инвестиций | BG3: Маржинальность продаж | BH3: Маржинальность прихода | BJ3: Xране- ние | BK3: Логис- тика | BL3: Доставка до места выдачи OZON | BM3: Между нас. пунктами/ Ср. миля Я.Маркет | BN3: Обра- ботка воз- врата | BO3: Цена воз- врата | BP3: МП → Клиент | BQ3: Комис- сия МП | BR3: Удер- жания МП Итог | BS3: НДС | BT3: Налог с НДС | BU3: Косты без закуп | BV3: Реально тратим | BW3: Приход на счет | BX3: При- быль
M4: WB | O4: OZON | Q4: Я.Маркет
A5: Прода- ем или нет | B5: FBS или FBO, выбран- ный в столбце AQ:AQ | C5: Название товара, для вашего удобства | D5: Вклю- чение отобра- жения строки. Можно выкл. то, чем не пользу- емся, чтобы не мешало | E5: Имя менеджера, для вашего удобства | F5: Вывод, продаем или не продаем товар, основываясь на типе и размере маржинальности во вкладке «▶️ Инструкция» | G5: Закупочная себесто- имость 1 единицы товара (1 штуки, если продаете по одному, сумма нескольких штук, если продаете комплектом) | H5: Цена, по которой планируется продажа 1 единицы товара (1 штуки, если продаете по одному, сумма нескольких штук, если продаете комплектом) | I5: Предполага- емый СПП от WB и Соинвест от OZON для правиль- ного расчета налогов | J5: Укажите кешбек, который вернете клиенту. Автоматом плюсуется 10% комиссии WB на этот кешбек | K5: % комиссии, на который OZON снижает свою комиссию, если мы будем участвовать в акции | L5: Пример- ное количест- во штук в постав- ляемой партии (может быть 1, для простоты расчетов) | M5: Название категории, подгружается автоматически после введения первых букв названия | N5: Комис- сия маркет- плейса подгру- жается автома- тически | O5: Название категории, подгружается автоматически после введения первых букв названия | P5: Комис- сия маркет- плейса подгру- жается автома- тически | Q5: Название категории, подгружается автоматически после введения первых букв названия | R5: Комис- сия маркет- плейса подгру- жается автома- тически | S5: Название склада для отгрузки. Если складов несколько, то задаем их в «▶️ Инструкция» в столбце Е:Е, а потом тут выбираем «Макс. из наших» | T5: Выбираем как отгружаем, коробами или монопал- летами | U5: Коэффициент территориального распределения за неделю из ЛК WB | V5: Индекс локали- зации из ЛК OZON | W5: Подробнее об этом – тут | Y5: Доля локальных продаж из ЛК Я.Маркет | Z5: Коэффициент приемки на WB тут | AA5: Цена приемки WB во время сдачи товара тут | AB5: При передаче до рекомендованного слота отгрузки – скидка 4% по FBS | AC5: Цена приемки OZON, формируется исходя из выбора, сделанного в «⚙️Настройки» | AD5: Цена приемки Я.Маркет, формируется исходя из выбора, сделанного в «⚙️Настройки» | AE5: Пример- ное время распро- дажи партии из колич- ества, указан- ного в К:К, поставля- емой на WB, для расчета цены хранения единицы | AF5: Высота, ширина и длина в санти- метрах 1 единицы товара (1 штуки, если продаете по одному, сумма несколь- ких штук, если продаете комплектом) | AI5: Объем или объем- ный вес выбира- ется и рассчи- тывается автома- тически | AJ5: Допол- нитель- ный объем сверх указан- ной на МП нормы выбира- ется и рассчи- тывается автома- тически | AK5: Вес товара нужно ввести вручную для расчета цены логистики | AL5: Стоимость эквайринга рассчиты- вается автомати- чески, исходя из выбора, сделанного в «▶️ Инструкция» | AM5: Стоимость Перевода платежей от Я.Маркет вам рассчиты- вается автомати- чески, исходя из выбора, сделанного в «⚙️Настройки» | AN5: Цена отгрузки 1 единицы или комплекта товара для FBO и/или FBS. Обычно эту цену определяет фулфилмент, она колеблется от 20 до 150 рублей за одну отгрузку. | AP5: Все дополни- тельные затраты для продажи — на логистику, дизайнера, фотографа и прочее на каждую единицу. Можно оставить ноль. | AQ5: Предпо- лагаемый или факти- ческий процент выкупа | AR5: Предпо- лагаемый или факти- ческий процент брака | AS5: Предпо- лагаемый или факти- ческий процент, заложен- ный на весь внутрен- ний и внешний маркетинг | AT5: Выбор вашего ИП, на основе которого будет считаться процент налога в столбце BH:BH | AU5: Выбор площадки, для которой делаем расчет | AV5: Выбор направле- ния, для которого делаем расчет | AW5: Цена заказа | AX5: Цена продажи | AY5: Процент рекалмы в ЧП | AZ5: Задайте тут желаемый CPO, чтобы справа получить нужный вам для этого ДРР | BA5: Получившийся ДРР из заданного левее CPO | BB5: Цена продажи минус CPO | BC5: Чистая прибыль с одной продажи, учитывая все те траты (косты), которые вы внесли | BD5: Чистая прибыль всей партии, указанной в K:K | BE5: Выручка до всех трат и комиссий от продажи партии, указанной в К:К | BF5: Рентабельность инвестиций (ROI) или отношение чистой прибыли к реально затраченным на продажу средствам | BG5: Отношение чистой прибыли от продажи к цене до СПП и соинвеста, по которой товар был продан | BH5: Отношение чистой прибыли от продажи к деньгам, пришедшим на счет после всех трат и комиссий маркет- плейсов | BJ5: Обнуляем хранение, потому что на ВБ оно стало беслптаным до 60 дней, на Озон и Я.маркет до 120 дней. | BK5: Расчет цены логис- тики | BL5: Расчет цены доставки до места выдачи на OZON | BM5: Расчет цены средней мили на Я.Маркет | BN5: Цена обра- ботки возврата | BO5: Цена воз- врата, с учетом всех дополни- тельных затрат на возврат | BP5: Цена хранения и логис- тики до получения товара клиентом | BQ5: Комис- сия маркет- плейса | BR5: Итоговая сумма всех удержа- ний маркет- плейса | BS5: Рассчет вашего НДС | BT5: Налог, рассчиты- ваемый на основании данных в «▶️ Инструкция» | BU5: Все траты (косты), без учета цены закупки товара | BV5: Расчет реальных трат до продажи и получе- ния выплат от маркет- плейса | BW5: Расчет денег, теорети- чески прихо- дящих на счет | BX5: Чистая прибыль с одной продажи, учитывая все те траты (косты), которые вы внесли
A6: =if(D6=true,if(F6=data!A$1,data!A$10,data!A$11),) | B6: =AV6 -> FBO | C6: 9785855906 | D6: FALSE | E6: Кристина | F6: {=IF(D6=TRUE,IF(IF(BG$3=VLOOKUP(AT6,{'▶️ Инструкция'!C:C,'▶️ Инструкция'!G:G},2,FALSE),BG6,BH6)>VLOOKUP(AT6,{'▶️ Инструкция'!C:C,'▶️ Инструкция'!N:N},2,FALSE),data!A$1,data!A$2),)} | G6: 560 | H6: 2905 | I6: 0.26 | J6: 0 | K6: =IF($D6,"🔒",) | L6: 0 | M6: Свитеры | N6: =IFERROR(__xludf.DUMMYFUNCTION("ArrayFormula(let(category,VLOOKUP($M6, {'📄 Комиссии'!$C:$C , '📄 Комиссии'!$B:$B}, 2, 0), data,MATCH('🔒 Доп. информация'!$J$15:$J203,TRANSPOSE(SPLIT(INDEX('▶️ Инструкция'!$Q:$Q,MATCH($AT6,'▶️ Инструкция'!$R:$R,0)+2),"", "",FALSE)),0), options,COUNTA( if"&"na( FILTER('🔒 Доп. информация'!$J$15:$J203,('🔒 Доп. информация'!$N$15:$N203=FALSE)*data*('🔒 Доп. информация'!$O$15:$O203=""Опция"")))), commission,VLOOKUP($M6,'📄 Комиссии'!$C:$E,IF($AV6=data!A$8,2,3),0), IF(NOT(ISBLANK($M6)),commission/100+ IFERROR(VL"&"OOKUP($AT6,{'▶️ Инструкция'!$R:$R,'▶️ Инструкция'!$AK:$AK},2,0)+ IF((( category = ""Одежда"")+( category = ""Обувь"" ))*((options+SUM( ifna( FILTER('🔒 Доп. информация'!$M$15:$M203,('🔒 Доп. информация'!$N$15:$N203=FALSE)*data*('🔒 Доп. информация'!$O$15:"&"$O203=""Пакет"")))))>=5), -5% + 2%, IF((options>=1)* (COUNTA( ifna( FILTER('🔒 Доп. информация'!$J$15:$J203,('🔒 Доп. информация'!$N$15:$N203=FALSE)*data*('🔒 Доп. информация'!$O$15:$O203=""Пакет""))))>=1)* (commission>=14.5)* (category<> ""Одежда"")*( c"&"ategory <> ""Обувь"" ),-3% + 2%,0))))))"),0.345) -> 0.345 | O6: =IF($D6,"🔒",) | Q6: =IF($D6,"🔒",) | S6: Макс. из наших | T6: Короб | U6: 1.17 | V6: =IF($D6,"🔒",) | W6: =IF($D6,"🔒",) | X6: =IF($D6,"🔒",) | Y6: =IF($D6,"🔒",) | Z6: 0 | AA6: 0 | AB6: =IF($D6,"🔒",) | AC6: =IF($D6,"🔒",) | AD6: =IF($D6,"🔒",) | AE6: 30 | AF6: 11 | AG6: 31 | AH6: 31 | AI6: =(AF6*AG6*AH6)/1000 -> 10.571 | AJ6: =if(AI6>1,(AI6-1),0) -> 9.571 | AK6: =IF($D6,"🔒",) | AL6: {=H6*(1-I6)*VLOOKUP(AT6,{'▶️ Инструкция'!C:C,'▶️ Инструкция'!AI:AI},2,false)} -> 64.491 | AM6: =IF($D6,"🔒",) | AN6: 0 | AO6: 0 | AP6: 0 | AQ6: 0.47 | AR6: 0 | AS6: 0.01 | AT6: ИП Копытина К.В. | AU6: WB | AV6: FBO | AW6: =AS6*H6 -> 29.05 | AX6: =(1/(AQ6))*H6*AS6 -> 61.808511 | AY6: =AX6/BC6 -> -0.18472524 | AZ6: 100 | BA6: =AZ6/H6 -> 0.034423408 | BB6: =H6-AW6 -> 2875.95 | BC6: =BX6 -> -334.597 | BD6: =BC6*L6 -> 0 | BE6: =H6*(1-I6)*L6 -> 0 | BF6: =IFERROR(BC6/BV6,) -> -0.47094566 | BG6: =IFERROR(BC6/H6,) -> -0.11517969 | BH6: =IFERROR(if(BW6>0,BC6/BW6,-BC6/BW6),) -> -0.890165 | BJ6: =IFERROR(__xludf.DUMMYFUNCTION("IF(AU6=data!A$5, IF(AV6=data!A$8, IF(T6=data!A$3, VLOOKUP(S6,filter('🔒 Доп. информация'!D:H,'🔒 Доп. информация'!C:C=T6),4,FALSE)+VLOOKUP(S6,filter('🔒 Доп. информация'!D:H,'🔒 Доп. информация'!C:C=T6),5,FALSE)*AJ6, IF(AND(MAX(AF6:AH6)<80,SUM(AF6:AH6)<=1"&"60,AI6<20,XLOOKUP(M6,'📄 Комиссии'!C:C,'📄 Комиссии'!B:B)<>""Продукты""), VLOOKUP(S6,filter('🔒 Доп. информация'!D:H,'🔒 Доп. информация'!C:C=data!$A$3),4,FALSE)+VLOOKUP(S6,filter('🔒 Доп. информация'!D:H,'🔒 Доп. информация'!C:C=data!$A$3),5,FALSE)*AJ6, "&"VLOOKUP(S6,filter('🔒 Доп. информация'!D:H,'🔒 Доп. информация'!C:C=T6),4,FALSE)*ROUNDUP(AF6*AG6*AH6*L6/(120*80*175))/L6) ) *(AE6/2) ,) ,)*0"),0.0) -> 0 | BK6: =IFERROR(__xludf.DUMMYFUNCTION("IF(AU6=data!A$5, IF(AI6<=1,IF(AI6<=0.8,IF(AI6<=0.6,IF(AI6<=0.4,IF(AI6<=0.2,23,26),29),30),32)*VLOOKUP(S6,filter('🔒 Доп. информация'!D:E,'🔒 Доп. информация'!C:C=T6),2,FALSE)/'🔒 Доп. информация'!$K$9, IF(AV6=data!A$8,U6,1)*VLOOKUP(S6,filter('🔒 Доп. инфо"&"рмация'!D:E,'🔒 Доп. информация'!C:C=T6),2,FALSE)+ IF(AV6=data!A$8,U6,1)*VLOOKUP(S6,filter('🔒 Доп. информация'!D:F,'🔒 Доп. информация'!C:C=T6),3,FALSE)*AJ6) ,0)"),631.7789399999999) -> 631.77894 | BL6: =IF($D6,"🔒",) | BM6: =IF($D6,"🔒",) | BN6: =VLOOKUP(T6,'🔒 Доп. информация'!J:P,7,false) -> 50 | BO6: =IF(AV6=data!A$9, (AA6+AO6+AP6+BJ6+BK6+BN6)+H6*AS6, (BJ6+BK6+BN6)+H6*AS6 ) -> 710.82894 | BP6: =AA6+BJ6+BK6 -> 631.77894 | BQ6: =H6*N6 -> 1002.225 | BR6: =BP6+BQ6+AS6*H6+((1-AQ6)/AQ6)*BO6+AL6+H6*J6*1.1 -> 2529.118 | BS6: {=IF(VLOOKUP(AT6,{'▶️ Инструкция'!C:C,'▶️ Инструкция'!Y:Y},2,FALSE)=data!A$15, H6*(1-I6), (H6-BR6)) *VLOOKUP(AT6,{'▶️ Инструкция'!C:C,'▶️ Инструкция'!AD:AD},2,FALSE)/(1+VLOOKUP(AT6,{'▶️ Инструкция'!C:C,'▶️ Инструкция'!AD:AD},2,FALSE))} -> 0 | BT6: {=IF(VLOOKUP(AT6,{'▶️ Инструкция'!C:C,'▶️ Инструкция'!Y:Y},2,FALSE)=data!A$15, H6*(1-I6)-BS6, (H6-BR6-BS6)) * VLOOKUP(AT6,{'▶️ Инструкция'!C:C,'▶️ Инструкция'!R:R},2,FALSE) +BS6} -> 150.479 | BU6: =(G6*AR6)+if(AV6=data!A$9,AO6,AN6)+AP6+BR6+BT6 -> 2679.597 | BV6: =(G6*AR6)+if(AV6=data!A$9,AO6,AN6)+AP6+BT6+G6 -> 710.479 | BW6: =H6-BR6 -> 375.882 | BX6: =BW6-BV6 -> -334.597
A7: =if(D7=true,if(F7=data!A$1,data!A$10,data!A$11),) -> ✅ | B7: =AV7 -> FBO | C7: Название товара | D7: TRUE | E7: Кристина | F7: {=IF(D7=TRUE,IF(IF(BG$3=VLOOKUP(AT7,{'▶️ Инструкция'!C:C,'▶️ Инструкция'!G:G},2,FALSE),BG7,BH7)>VLOOKUP(AT7,{'▶️ Инструкция'!C:C,'▶️ Инструкция'!N:N},2,FALSE),data!A$1,data!A$2),)} -> Срочно закупаем и продаем 💸 | G7: 560 | H7: 2905 | I7: 0.26 | J7: 0 | K7: =IF($D7,"🔒",) -> 🔒 | L7: 0 | M7: Свитеры | N7: =IFERROR(__xludf.DUMMYFUNCTION("ArrayFormula(let(category,VLOOKUP($M7, {'📄 Комиссии'!$C:$C , '📄 Комиссии'!$B:$B}, 2, 0), data,MATCH('🔒 Доп. информация'!$J$15:$J203,TRANSPOSE(SPLIT(INDEX('▶️ Инструкция'!$Q:$Q,MATCH($AT7,'▶️ Инструкция'!$R:$R,0)+2),"", "",FALSE)),0), options,COUNTA( if"&"na( FILTER('🔒 Доп. информация'!$J$15:$J203,('🔒 Доп. информация'!$N$15:$N203=FALSE)*data*('🔒 Доп. информация'!$O$15:$O203=""Опция"")))), commission,VLOOKUP($M7,'📄 Комиссии'!$C:$E,IF($AV7=data!A$8,2,3),0), IF(NOT(ISBLANK($M7)),commission/100+ IFERROR(VL"&"OOKUP($AT7,{'▶️ Инструкция'!$R:$R,'▶️ Инструкция'!$AK:$AK},2,0)+ IF((( category = ""Одежда"")+( category = ""Обувь"" ))*((options+SUM( ifna( FILTER('🔒 Доп. информация'!$M$15:$M203,('🔒 Доп. информация'!$N$15:$N203=FALSE)*data*('🔒 Доп. информация'!$O$15:"&"$O203=""Пакет"")))))>=5), -5% + 2%, IF((options>=1)* (COUNTA( ifna( FILTER('🔒 Доп. информация'!$J$15:$J203,('🔒 Доп. информация'!$N$15:$N203=FALSE)*data*('🔒 Доп. информация'!$O$15:$O203=""Пакет""))))>=1)* (commission>=14.5)* (category<> ""Одежда"")*( c"&"ategory <> ""Обувь"" ),-3% + 2%,0))))))"),0.345) -> 0.345 | O7: =IF($D7,"🔒",) -> 🔒 | Q7: =IF($D7,"🔒",) -> 🔒 | S7: FBS: Маркетплейс: Уральский федеральный округ СГТ | T7: Короб | U7: 1.17 | V7: =IF($D7,"🔒",) -> 🔒 | W7: =IF($D7,"🔒",) -> 🔒 | X7: =IF($D7,"🔒",) -> 🔒 | Y7: =IF($D7,"🔒",) -> 🔒 | Z7: 0 | AA7: =1.7*(1+AJ7)*Z7 -> 0 | AB7: =IF($D7,"🔒",) -> 🔒 | AC7: =IF($D7,"🔒",) -> 🔒 | AD7: =IF($D7,"🔒",) -> 🔒 | AE7: 30 | AF7: 11 | AG7: 31 | AH7: 31 | AI7: =(AF7*AG7*AH7)/1000 -> 10.571 | AJ7: =if(AI7>1,(AI7-1),0) -> 9.571 | AK7: =IF($D7,"🔒",) -> 🔒 | AL7: {=H7*(1-I7)*VLOOKUP(AT7,{'▶️ Инструкция'!C:C,'▶️ Инструкция'!AI:AI},2,false)} -> 64.491 | AM7: =IF($D7,"🔒",) -> 🔒 | AN7: 0 | AO7: 0 | AP7: 150 | AQ7: 0.47 | AR7: 0.003 | AS7: 0 | AT7: ИП Копытина К.В. | AU7: WB | AV7: FBO | AW7: =AS7*H7 -> 0 | AX7: =(1/(AQ7))*H7*AS7 -> 0 | AY7: =AX7/BC7 -> 0 | AZ7: 100 | BA7: =AZ7/H7 -> 0.034423408 | BB7: =H7-AW7 -> 2905 | BC7: =BX7 -> 471.67185 | BD7: =BC7*L7 -> 0 | BE7: =H7*(1-I7)*L7 -> 0 | BF7: =IFERROR(BC7/BV7,) -> 0.54708221 | BG7: =IFERROR(BC7/H7,) -> 0.16236553 | BH7: =IFERROR(if(BW7>0,BC7/BW7,-BC7/BW7),) -> 0.35362194 | BJ7: =IFERROR(__xludf.DUMMYFUNCTION("IF(AU7=data!A$5, IF(AV7=data!A$8, IF(T7=data!A$3, VLOOKUP(S7,filter('🔒 Доп. информация'!D:H,'🔒 Доп. информация'!C:C=T7),4,FALSE)+VLOOKUP(S7,filter('🔒 Доп. информация'!D:H,'🔒 Доп. информация'!C:C=T7),5,FALSE)*AJ7, IF(AND(MAX(AF7:AH7)<80,SUM(AF7:AH7)<=1"&"60,AI7<20,XLOOKUP(M7,'📄 Комиссии'!C:C,'📄 Комиссии'!B:B)<>""Продукты""), VLOOKUP(S7,filter('🔒 Доп. информация'!D:H,'🔒 Доп. информация'!C:C=data!$A$3),4,FALSE)+VLOOKUP(S7,filter('🔒 Доп. информация'!D:H,'🔒 Доп. информация'!C:C=data!$A$3),5,FALSE)*AJ7, "&"VLOOKUP(S7,filter('🔒 Доп. информация'!D:H,'🔒 Доп. информация'!C:C=T7),4,FALSE)*ROUNDUP(AF7*AG7*AH7*L7/(120*80*175))/L7) ) *(AE7/2) ,) ,)*0"),0.0) -> 0 | BK7: =IFERROR(__xludf.DUMMYFUNCTION("IF(AU7=data!A$5, IF(AI7<=1,IF(AI7<=0.8,IF(AI7<=0.6,IF(AI7<=0.4,IF(AI7<=0.2,23,26),29),30),32)*VLOOKUP(S7,filter('🔒 Доп. информация'!D:E,'🔒 Доп. информация'!C:C=T7),2,FALSE)/'🔒 Доп. информация'!$K$9, IF(AV7=data!A$8,U7,1)*VLOOKUP(S7,filter('🔒 Доп. инфо"&"рмация'!D:E,'🔒 Доп. информация'!C:C=T7),2,FALSE)+ IF(AV7=data!A$8,U7,1)*VLOOKUP(S7,filter('🔒 Доп. информация'!D:F,'🔒 Доп. информация'!C:C=T7),3,FALSE)*AJ7) ,0)"),210.59297999999998) -> 210.59298 | BL7: =IF($D7,"🔒",) -> 🔒 | BM7: =IF($D7,"🔒",) -> 🔒 | BN7: =VLOOKUP(T7,'🔒 Доп. информация'!J:P,7,false) -> 50 | BO7: =IF(AV7=data!A$9, (AA7+AO7+AP7+BJ7+BK7+BN7)+H7*AS7, (BJ7+BK7+BN7)+H7*AS7 ) -> 260.59298 | BP7: =AA7+BJ7+BK7 -> 210.59298 | BQ7: =H7*N7 -> 1002.225 | BR7: =BP7+BQ7+AS7*H7+((1-AQ7)/AQ7)*BO7+AL7+H7*J7 -> 1571.1691 | BS7: {=IF(VLOOKUP(AT7,{'▶️ Инструкция'!C:C,'▶️ Инструкция'!Y:Y},2,FALSE)=data!A$15, H7*(1-I7), (H7-BR7)) *VLOOKUP(AT7,{'▶️ Инструкция'!C:C,'▶️ Инструкция'!AD:AD},2,FALSE)/(1+VLOOKUP(AT7,{'▶️ Инструкция'!C:C,'▶️ Инструкция'!AD:AD},2,FALSE))} -> 0 | BT7: {=IF(VLOOKUP(AT7,{'▶️ Инструкция'!C:C,'▶️ Инструкция'!Y:Y},2,FALSE)=data!A$15, H7*(1-I7)-BS7, (H7-BR7-BS7)) * VLOOKUP(AT7,{'▶️ Инструкция'!C:C,'▶️ Инструкция'!R:R},2,FALSE) +BS7} -> 150.479 | BU7: =(G7*AR7)+if(AV7=data!A$9,AO7,AN7)+AP7+BR7+BT7 -> 1873.3281 | BV7: =(G7*AR7)+if(AV7=data!A$9,AO7,AN7)+AP7+BT7+G7 -> 862.159 | BW7: =H7-BR7 -> 1333.8309 | BX7: =BW7-BV7 -> 471.67185
A8: =if(D8=true,if(F8=data!A$1,data!A$10,data!A$11),) -> ✅ | B8: =AV8 -> FBO | C8: Название товара | D8: TRUE | E8: Кристина | F8: {=IF(D8=TRUE,IF(IF(BG$3=VLOOKUP(AT8,{'▶️ Инструкция'!C:C,'▶️ Инструкция'!G:G},2,FALSE),BG8,BH8)>VLOOKUP(AT8,{'▶️ Инструкция'!C:C,'▶️ Инструкция'!N:N},2,FALSE),data!A$1,data!A$2),)} -> Срочно закупаем и продаем 💸 | G8: 0 | H8: 1000 | I8: 0 | J8: 0 | K8: =IF($D8,"🔒",) -> 🔒 | L8: 0 | M8: Лопатки игрушечные | N8: =IFERROR(__xludf.DUMMYFUNCTION("ArrayFormula(let(category,VLOOKUP($M8, {'📄 Комиссии'!$C:$C , '📄 Комиссии'!$B:$B}, 2, 0), data,MATCH('🔒 Доп. информация'!$J$15:$J203,TRANSPOSE(SPLIT(INDEX('▶️ Инструкция'!$Q:$Q,MATCH($AT8,'▶️ Инструкция'!$R:$R,0)+2),"", "",FALSE)),0), options,COUNTA( if"&"na( FILTER('🔒 Доп. информация'!$J$15:$J203,('🔒 Доп. информация'!$N$15:$N203=FALSE)*data*('🔒 Доп. информация'!$O$15:$O203=""Опция"")))), commission,VLOOKUP($M8,'📄 Комиссии'!$C:$E,IF($AV8=data!A$8,2,3),0), IF(NOT(ISBLANK($M8)),commission/100+ IFERROR(VL"&"OOKUP($AT8,{'▶️ Инструкция'!$R:$R,'▶️ Инструкция'!$AK:$AK},2,0)+ IF((( category = ""Одежда"")+( category = ""Обувь"" ))*((options+SUM( ifna( FILTER('🔒 Доп. информация'!$M$15:$M203,('🔒 Доп. информация'!$N$15:$N203=FALSE)*data*('🔒 Доп. информация'!$O$15:"&"$O203=""Пакет"")))))>=5), -5% + 2%, IF((options>=1)* (COUNTA( ifna( FILTER('🔒 Доп. информация'!$J$15:$J203,('🔒 Доп. информация'!$N$15:$N203=FALSE)*data*('🔒 Доп. информация'!$O$15:$O203=""Пакет""))))>=1)* (commission>=14.5)* (category<> ""Одежда"")*( c"&"ategory <> ""Обувь"" ),-3% + 2%,0))))))"),0.285) -> 0.285 | O8: =IF($D8,"🔒",) -> 🔒 | Q8: =IF($D8,"🔒",) -> 🔒 | S8: Макс. из наших | T8: Короб | U8: 1 | V8: =IF($D8,"🔒",) -> 🔒 | W8: =IF($D8,"🔒",) -> 🔒 | X8: =IF($D8,"🔒",) -> 🔒 | Y8: =IF($D8,"🔒",) -> 🔒 | Z8: 0 | AA8: =1.7*(1+AJ8)*Z8 -> 0 | AB8: =IF($D8,"🔒",) -> 🔒 | AC8: =IF($D8,"🔒",) -> 🔒 | AD8: =IF($D8,"🔒",) -> 🔒 | AE8: 60 | AF8: 0 | AG8: 0 | AH8: 0 | AI8: =(AF8*AG8*AH8)/1000 -> 0 | AJ8: =if(AI8>1,(AI8-1),0) -> 0 | AK8: =IF($D8,"🔒",) -> 🔒 | AL8: {=H8*(1-I8)*VLOOKUP(AT8,{'▶️ Инструкция'!C:C,'▶️ Инструкция'!AI:AI},2,false)} -> 30 | AM8: =IF($D8,"🔒",) -> 🔒 | AN8: 0 | AO8: 0 | AP8: 0 | AQ8: 1 | AR8: 0.03 | AS8: 0 | AT8: ИП Копытина К.В. | AU8: WB | AV8: FBO | AW8: =AS8*H8 -> 0 | AX8: =(1/(AQ8))*H8*AS8 -> 0 | AY8: =AX8/BC8 -> 0 | AZ8: 250 | BA8: =AZ8/H8 -> 0.25 | BB8: =H8-AW8 -> 1000 | BC8: =BX8 -> 546 | BD8: =BC8*L8 -> 0 | BE8: =H8*(1-I8)*L8 -> 0 | BF8: =IFERROR(BC8/BV8,) -> 7.8 | BG8: =IFERROR(BC8/H8,) -> 0.546 | BH8: =IFERROR(if(BW8>0,BC8/BW8,-BC8/BW8),) -> 0.88636364 | BJ8: =IFERROR(__xludf.DUMMYFUNCTION("IF(AU8=data!A$5, IF(AV8=data!A$8, IF(T8=data!A$3, VLOOKUP(S8,filter('🔒 Доп. информация'!D:H,'🔒 Доп. информация'!C:C=T8),4,FALSE)+VLOOKUP(S8,filter('🔒 Доп. информация'!D:H,'🔒 Доп. информация'!C:C=T8),5,FALSE)*AJ8, IF(AND(MAX(AF8:AH8)<80,SUM(AF8:AH8)<=1"&"60,AI8<20,XLOOKUP(M8,'📄 Комиссии'!C:C,'📄 Комиссии'!B:B)<>""Продукты""), VLOOKUP(S8,filter('🔒 Доп. информация'!D:H,'🔒 Доп. информация'!C:C=data!$A$3),4,FALSE)+VLOOKUP(S8,filter('🔒 Доп. информация'!D:H,'🔒 Доп. информация'!C:C=data!$A$3),5,FALSE)*AJ8, "&"VLOOKUP(S8,filter('🔒 Доп. информация'!D:H,'🔒 Доп. информация'!C:C=T8),4,FALSE)*ROUNDUP(AF8*AG8*AH8*L8/(120*80*175))/L8) ) *(AE8/2) ,) ,)*0"),0.0) -> 0 | BK8: =IFERROR(__xludf.DUMMYFUNCTION("IF(AU8=data!A$5, IF(AI8<=1,IF(AI8<=0.8,IF(AI8<=0.6,IF(AI8<=0.4,IF(AI8<=0.2,23,26),29),30),32)*VLOOKUP(S8,filter('🔒 Доп. информация'!D:E,'🔒 Доп. информация'!C:C=T8),2,FALSE)/'🔒 Доп. информация'!$K$9, IF(AV8=data!A$8,U8,1)*VLOOKUP(S8,filter('🔒 Доп. инфо"&"рмация'!D:E,'🔒 Доп. информация'!C:C=T8),2,FALSE)+ IF(AV8=data!A$8,U8,1)*VLOOKUP(S8,filter('🔒 Доп. информация'!D:F,'🔒 Доп. информация'!C:C=T8),3,FALSE)*AJ8) ,0)"),69.0) -> 69 | BL8: =IF($D8,"🔒",) -> 🔒 | BM8: =IF($D8,"🔒",) -> 🔒 | BN8: =VLOOKUP(T8,'🔒 Доп. информация'!J:P,7,false) -> 50 | BO8: =IF(AV8=data!A$9, (AA8+AO8+AP8+BJ8+BK8+BN8)+H8*AS8, (BJ8+BK8+BN8)+H8*AS8 ) -> 119 | BP8: =AA8+BJ8+BK8 -> 69 | BQ8: =H8*N8 -> 285 | BR8: =BP8+BQ8+AS8*H8+((1-AQ8)/AQ8)*BO8+AL8+H8*J8*1.1 -> 384 | BS8: {=IF(VLOOKUP(AT8,{'▶️ Инструкция'!C:C,'▶️ Инструкция'!Y:Y},2,FALSE)=data!A$15, H8*(1-I8), (H8-BR8)) *VLOOKUP(AT8,{'▶️ Инструкция'!C:C,'▶️ Инструкция'!AD:AD},2,FALSE)/(1+VLOOKUP(AT8,{'▶️ Инструкция'!C:C,'▶️ Инструкция'!AD:AD},2,FALSE))} -> 0 | BT8: {=IF(VLOOKUP(AT8,{'▶️ Инструкция'!C:C,'▶️ Инструкция'!Y:Y},2,FALSE)=data!A$15, H8*(1-I8)-BS8, (H8-BR8-BS8)) * VLOOKUP(AT8,{'▶️ Инструкция'!C:C,'▶️ Инструкция'!R:R},2,FALSE) +BS8} -> 70 | BU8: =(G8*AR8)+if(AV8=data!A$9,AO8,AN8)+AP8+BR8+BT8 -> 454 | BV8: =(G8*AR8)+if(AV8=data!A$9,AO8,AN8)+AP8+BT8+G8 -> 70 | BW8: =H8-BR8 -> 616 | BX8: =BW8-BV8 -> 546
A9: =if(D9=true,if(F9=data!A$1,data!A$10,data!A$11),) -> ✅ | B9: =AV9 -> FBS | C9: Название товара | D9: TRUE | E9: Кристина | F9: {=IF(D9=TRUE,IF(IF(BG$3=VLOOKUP(AT9,{'▶️ Инструкция'!C:C,'▶️ Инструкция'!G:G},2,FALSE),BG9,BH9)>VLOOKUP(AT9,{'▶️ Инструкция'!C:C,'▶️ Инструкция'!N:N},2,FALSE),data!A$1,data!A$2),)} -> Срочно закупаем и продаем 💸 | G9: 0 | H9: 1000 | I9: 0 | J9: 0 | K9: =IF($D9,"🔒",) -> 🔒 | L9: 0 | M9: Лопатки игрушечные | N9: =IFERROR(__xludf.DUMMYFUNCTION("ArrayFormula(let(category,VLOOKUP($M9, {'📄 Комиссии'!$C:$C , '📄 Комиссии'!$B:$B}, 2, 0), data,MATCH('🔒 Доп. информация'!$J$15:$J203,TRANSPOSE(SPLIT(INDEX('▶️ Инструкция'!$Q:$Q,MATCH($AT9,'▶️ Инструкция'!$R:$R,0)+2),"", "",FALSE)),0), options,COUNTA( if"&"na( FILTER('🔒 Доп. информация'!$J$15:$J203,('🔒 Доп. информация'!$N$15:$N203=FALSE)*data*('🔒 Доп. информация'!$O$15:$O203=""Опция"")))), commission,VLOOKUP($M9,'📄 Комиссии'!$C:$E,IF($AV9=data!A$8,2,3),0), IF(NOT(ISBLANK($M9)),commission/100+ IFERROR(VL"&"OOKUP($AT9,{'▶️ Инструкция'!$R:$R,'▶️ Инструкция'!$AK:$AK},2,0)+ IF((( category = ""Одежда"")+( category = ""Обувь"" ))*((options+SUM( ifna( FILTER('🔒 Доп. информация'!$M$15:$M203,('🔒 Доп. информация'!$N$15:$N203=FALSE)*data*('🔒 Доп. информация'!$O$15:"&"$O203=""Пакет"")))))>=5), -5% + 2%, IF((options>=1)* (COUNTA( ifna( FILTER('🔒 Доп. информация'!$J$15:$J203,('🔒 Доп. информация'!$N$15:$N203=FALSE)*data*('🔒 Доп. информация'!$O$15:$O203=""Пакет""))))>=1)* (commission>=14.5)* (category<> ""Одежда"")*( c"&"ategory <> ""Обувь"" ),-3% + 2%,0))))))"),0.32) -> 0.32 | O9: =IF($D9,"🔒",) -> 🔒 | Q9: =IF($D9,"🔒",) -> 🔒 | S9: СЦ Оренбург Центральная | T9: Короб | U9: 1 | V9: =IF($D9,"🔒",) -> 🔒 | W9: =IF($D9,"🔒",) -> 🔒 | X9: =IF($D9,"🔒",) -> 🔒 | Y9: =IF($D9,"🔒",) -> 🔒 | Z9: 0 | AA9: =1.7*(1+AJ9)*Z9 -> 0 | AB9: =IF($D9,"🔒",) -> 🔒 | AC9: =IF($D9,"🔒",) -> 🔒 | AD9: =IF($D9,"🔒",) -> 🔒 | AE9: 30 | AF9: 0 | AG9: 0 | AH9: 0 | AI9: =(AF9*AG9*AH9)/1000 -> 0 | AJ9: =if(AI9>1,(AI9-1),0) -> 0 | AK9: =IF($D9,"🔒",) -> 🔒 | AL9: {=H9*(1-I9)*VLOOKUP(AT9,{'▶️ Инструкция'!C:C,'▶️ Инструкция'!AI:AI},2,false)} -> 30 | AM9: =IF($D9,"🔒",) -> 🔒 | AN9: 0 | AO9: 0 | AP9: 0 | AQ9: 1 | AR9: 0 | AS9: 0 | AT9: ИП Копытина К.В. | AU9: WB | AV9: FBS | AW9: =AS9*H9 -> 0 | AX9: =(1/(AQ9))*H9*AS9 -> 0 | AY9: =AX9/BC9 -> 0 | AZ9: 250 | BA9: =AZ9/H9 -> 0.25 | BB9: =H9-AW9 -> 1000 | BC9: =BX9 -> 535.15 | BD9: =BC9*L9 -> 0 | BE9: =H9*(1-I9)*L9 -> 0 | BF9: =IFERROR(BC9/BV9,) -> 7.645 | BG9: =IFERROR(BC9/H9,) -> 0.53515 | BH9: =IFERROR(if(BW9>0,BC9/BW9,-BC9/BW9),) -> 0.8843262 | BJ9: =IFERROR(__xludf.DUMMYFUNCTION("IF(AU9=data!A$5, IF(AV9=data!A$8, IF(T9=data!A$3, VLOOKUP(S9,filter('🔒 Доп. информация'!D:H,'🔒 Доп. информация'!C:C=T9),4,FALSE)+VLOOKUP(S9,filter('🔒 Доп. информация'!D:H,'🔒 Доп. информация'!C:C=T9),5,FALSE)*AJ9, IF(AND(MAX(AF9:AH9)<80,SUM(AF9:AH9)<=1"&"60,AI9<20,XLOOKUP(M9,'📄 Комиссии'!C:C,'📄 Комиссии'!B:B)<>""Продукты""), VLOOKUP(S9,filter('🔒 Доп. информация'!D:H,'🔒 Доп. информация'!C:C=data!$A$3),4,FALSE)+VLOOKUP(S9,filter('🔒 Доп. информация'!D:H,'🔒 Доп. информация'!C:C=data!$A$3),5,FALSE)*AJ9, "&"VLOOKUP(S9,filter('🔒 Доп. информация'!D:H,'🔒 Доп. информация'!C:C=T9),4,FALSE)*ROUNDUP(AF9*AG9*AH9*L9/(120*80*175))/L9) ) *(AE9/2) ,) ,)*0"),0.0) -> 0 | BK9: =IFERROR(__xludf.DUMMYFUNCTION("IF(AU9=data!A$5, IF(AI9<=1,IF(AI9<=0.8,IF(AI9<=0.6,IF(AI9<=0.4,IF(AI9<=0.2,23,26),29),30),32)*VLOOKUP(S9,filter('🔒 Доп. информация'!D:E,'🔒 Доп. информация'!C:C=T9),2,FALSE)/'🔒 Доп. информация'!$K$9, IF(AV9=data!A$8,U9,1)*VLOOKUP(S9,filter('🔒 Доп. инфо"&"рмация'!D:E,'🔒 Доп. информация'!C:C=T9),2,FALSE)+ IF(AV9=data!A$8,U9,1)*VLOOKUP(S9,filter('🔒 Доп. информация'!D:F,'🔒 Доп. информация'!C:C=T9),3,FALSE)*AJ9) ,0)"),44.85) -> 44.85 | BL9: =IF($D9,"🔒",) -> 🔒 | BM9: =IF($D9,"🔒",) -> 🔒 | BN9: =VLOOKUP(T9,'🔒 Доп. информация'!J:P,7,false) -> 50 | BO9: =IF(AV9=data!A$9, (AA9+AO9+AP9+BJ9+BK9+BN9)+H9*AS9, (BJ9+BK9+BN9)+H9*AS9 ) -> 94.85 | BP9: =AA9+BJ9+BK9 -> 44.85 | BQ9: =H9*N9 -> 320 | BR9: =BP9+BQ9+AS9*H9+((1-AQ9)/AQ9)*BO9+AL9+H9*J9*1.1 -> 394.85 | BS9: {=IF(VLOOKUP(AT9,{'▶️ Инструкция'!C:C,'▶️ Инструкция'!Y:Y},2,FALSE)=data!A$15, H9*(1-I9), (H9-BR9)) *VLOOKUP(AT9,{'▶️ Инструкция'!C:C,'▶️ Инструкция'!AD:AD},2,FALSE)/(1+VLOOKUP(AT9,{'▶️ Инструкция'!C:C,'▶️ Инструкция'!AD:AD},2,FALSE))} -> 0 | BT9: {=IF(VLOOKUP(AT9,{'▶️ Инструкция'!C:C,'▶️ Инструкция'!Y:Y},2,FALSE)=data!A$15, H9*(1-I9)-BS9, (H9-BR9-BS9)) * VLOOKUP(AT9,{'▶️ Инструкция'!C:C,'▶️ Инструкция'!R:R},2,FALSE) +BS9} -> 70 | BU9: =(G9*AR9)+if(AV9=data!A$9,AO9,AN9)+AP9+BR9+BT9 -> 464.85 | BV9: =(G9*AR9)+if(AV9=data!A$9,AO9,AN9)+AP9+BT9+G9 -> 70 | BW9: =H9-BR9 -> 605.15 | BX9: =BW9-BV9 -> 535.15
A10: =if(D10=true,if(F10=data!A$1,data!A$10,data!A$11),) -> ✅ | B10: =AV10 -> FBO | C10: Название товара | D10: TRUE | E10: Флюза | F10: {=IF(D10=TRUE,IF(IF(BG$3=VLOOKUP(AT10,{'▶️ Инструкция'!C:C,'▶️ Инструкция'!G:G},2,FALSE),BG10,BH10)>VLOOKUP(AT10,{'▶️ Инструкция'!C:C,'▶️ Инструкция'!N:N},2,FALSE),data!A$1,data!A$2),)} -> Срочно закупаем и продаем 💸 | G10: 146 | H10: 650 | I10: 0 | J10: 0 | K10: =IF($D10,"🔒",) -> 🔒 | L10: 0 | M10: Накладные ресницы | N10: =IFERROR(__xludf.DUMMYFUNCTION("ArrayFormula(let(category,VLOOKUP($M10, {'📄 Комиссии'!$C:$C , '📄 Комиссии'!$B:$B}, 2, 0), data,MATCH('🔒 Доп. информация'!$J$15:$J203,TRANSPOSE(SPLIT(INDEX('▶️ Инструкция'!$Q:$Q,MATCH($AT10,'▶️ Инструкция'!$R:$R,0)+2),"", "",FALSE)),0), options,COUNTA( "&"ifna( FILTER('🔒 Доп. информация'!$J$15:$J203,('🔒 Доп. информация'!$N$15:$N203=FALSE)*data*('🔒 Доп. информация'!$O$15:$O203=""Опция"")))), commission,VLOOKUP($M10,'📄 Комиссии'!$C:$E,IF($AV10=data!A$8,2,3),0), IF(NOT(ISBLANK($M10)),commission/100+ IFERR"&"OR(VLOOKUP($AT10,{'▶️ Инструкция'!$R:$R,'▶️ Инструкция'!$AK:$AK},2,0)+ IF((( category = ""Одежда"")+( category = ""Обувь"" ))*((options+SUM( ifna( FILTER('🔒 Доп. информация'!$M$15:$M203,('🔒 Доп. информация'!$N$15:$N203=FALSE)*data*('🔒 Доп. информация'!"&"$O$15:$O203=""Пакет"")))))>=5), -5% + 2%, IF((options>=1)* (COUNTA( ifna( FILTER('🔒 Доп. информация'!$J$15:$J203,('🔒 Доп. информация'!$N$15:$N203=FALSE)*data*('🔒 Доп. информация'!$O$15:$O203=""Пакет""))))>=1)* (commission>=14.5)* (category<> ""Одежда"&""")*( category <> ""Обувь"" ),-3% + 2%,0))))))"),0.325) -> 0.325 | O10: =IF($D10,"🔒",) -> 🔒 | Q10: =IF($D10,"🔒",) -> 🔒 | S10: Электросталь | T10: Короб | U10: 1 | V10: =IF($D10,"🔒",) -> 🔒 | W10: =IF($D10,"🔒",) -> 🔒 | X10: =IF($D10,"🔒",) -> 🔒 | Y10: =IF($D10,"🔒",) -> 🔒 | Z10: 0 | AA10: =1.7*(1+AJ10)*Z10 -> 0 | AB10: =IF($D10,"🔒",) -> 🔒 | AC10: =IF($D10,"🔒",) -> 🔒 | AD10: =IF($D10,"🔒",) -> 🔒 | AE10: 30 | AF10: 3 | AG10: 16 | AH10: 18 | AI10: =(AF10*AG10*AH10)/1000 -> 0.864 | AJ10: =if(AI10>1,(AI10-1),0) -> 0 | AK10: =IF($D10,"🔒",) -> 🔒 | AL10: {=H10*(1-I10)*VLOOKUP(AT10,{'▶️ Инструкция'!C:C,'▶️ Инструкция'!AI:AI},2,false)} -> 13 | AM10: =IF($D10,"🔒",) -> 🔒 | AN10: 0 | AO10: 0 | AP10: 0 | AQ10: 1 | AR10: 0 | AS10: 0.01 | AT10: ип F | AU10: WB | AV10: FBO | AW10: =AS10*H10 -> 6.5 | AX10: =(1/(AQ10))*H10*AS10 -> 6.5 | AY10: =AX10/BC10 -> 0.033704952 | AZ10: 250 | BA10: =AZ10/H10 -> 0.38461538 | BB10: =H10-AW10 -> 643.5 | BC10: =BX10 -> 192.85 | BD10: =BC10*L10 -> 0 | BE10: =H10*(1-I10)*L10 -> 0 | BF10: =IFERROR(BC10/BV10,) -> 1.1212209 | BG10: =IFERROR(BC10/H10,) -> 0.29669231 | BH10: =IFERROR(if(BW10>0,BC10/BW10,-BC10/BW10),) -> 0.52857339 | BJ10: =IFERROR(__xludf.DUMMYFUNCTION("IF(AU10=data!A$5, IF(AV10=data!A$8, IF(T10=data!A$3, VLOOKUP(S10,filter('🔒 Доп. информация'!D:H,'🔒 Доп. информация'!C:C=T10),4,FALSE)+VLOOKUP(S10,filter('🔒 Доп. информация'!D:H,'🔒 Доп. информация'!C:C=T10),5,FALSE)*AJ10, IF(AND(MAX(AF10:AH10)<80,SUM(A"&"F10:AH10)<=160,AI10<20,XLOOKUP(M10,'📄 Комиссии'!C:C,'📄 Комиссии'!B:B)<>""Продукты""), VLOOKUP(S10,filter('🔒 Доп. информация'!D:H,'🔒 Доп. информация'!C:C=data!$A$3),4,FALSE)+VLOOKUP(S10,filter('🔒 Доп. информация'!D:H,'🔒 Доп. информация'!C:C=data!$A$3"&"),5,FALSE)*AJ10, VLOOKUP(S10,filter('🔒 Доп. информация'!D:H,'🔒 Доп. информация'!C:C=T10),4,FALSE)*ROUNDUP(AF10*AG10*AH10*L10/(120*80*175))/L10) ) *(AE10/2) ,) ,)*0"),0.0) -> 0 | BK10: =IFERROR(__xludf.DUMMYFUNCTION("IF(AU10=data!A$5, IF(AI10<=1,IF(AI10<=0.8,IF(AI10<=0.6,IF(AI10<=0.4,IF(AI10<=0.2,23,26),29),30),32)*VLOOKUP(S10,filter('🔒 Доп. информация'!D:E,'🔒 Доп. информация'!C:C=T10),2,FALSE)/'🔒 Доп. информация'!$K$9, IF(AV10=data!A$8,U10,1)*VLOOKUP(S10,filter('"&"🔒 Доп. информация'!D:E,'🔒 Доп. информация'!C:C=T10),2,FALSE)+ IF(AV10=data!A$8,U10,1)*VLOOKUP(S10,filter('🔒 Доп. информация'!D:F,'🔒 Доп. информация'!C:C=T10),3,FALSE)*AJ10) ,0)"),54.4) -> 54.4 | BL10: =IF($D10,"🔒",) -> 🔒 | BM10: =IF($D10,"🔒",) -> 🔒 | BN10: =VLOOKUP(T10,'🔒 Доп. информация'!J:P,7,false) -> 50 | BO10: =IF(AV10=data!A$9, (AA10+AO10+AP10+BJ10+BK10+BN10)+H10*AS10, (BJ10+BK10+BN10)+H10*AS10 ) -> 110.9 | BP10: =AA10+BJ10+BK10 -> 54.4 | BQ10: =H10*N10 -> 211.25 | BR10: =BP10+BQ10+AS10*H10+((1-AQ10)/AQ10)*BO10+AL10+H10*J10*1.1 -> 285.15 | BS10: {=IF(VLOOKUP(AT10,{'▶️ Инструкция'!C:C,'▶️ Инструкция'!Y:Y},2,FALSE)=data!A$15, H10*(1-I10), (H10-BR10)) *VLOOKUP(AT10,{'▶️ Инструкция'!C:C,'▶️ Инструкция'!AD:AD},2,FALSE)/(1+VLOOKUP(AT10,{'▶️ Инструкция'!C:C,'▶️ Инструкция'!AD:AD},2,FALSE))} -> 0 | BT10: {=IF(VLOOKUP(AT10,{'▶️ Инструкция'!C:C,'▶️ Инструкция'!Y:Y},2,FALSE)=data!A$15, H10*(1-I10)-BS10, (H10-BR10-BS10)) * VLOOKUP(AT10,{'▶️ Инструкция'!C:C,'▶️ Инструкция'!R:R},2,FALSE) +BS10} -> 26 | BU10: =(G10*AR10)+if(AV10=data!A$9,AO10,AN10)+AP10+BR10+BT10 -> 311.15 | BV10: =(G10*AR10)+if(AV10=data!A$9,AO10,AN10)+AP10+BT10+G10 -> 172 | BW10: =H10-BR10 -> 364.85 | BX10: =BW10-BV10 -> 192.85
A11: =if(D11=true,if(F11=data!A$1,data!A$10,data!A$11),) -> ✅ | B11: =AV11 -> FBO | C11: ресницы | D11: TRUE | E11: Имя | F11: {=IF(D11=TRUE,IF(IF(BG$3=VLOOKUP(AT11,{'▶️ Инструкция'!C:C,'▶️ Инструкция'!G:G},2,FALSE),BG11,BH11)>VLOOKUP(AT11,{'▶️ Инструкция'!C:C,'▶️ Инструкция'!N:N},2,FALSE),data!A$1,data!A$2),)} -> Срочно закупаем и продаем 💸 | G11: 146 | H11: 600 | I11: 0 | J11: 0 | K11: =IF($D11,"🔒",) -> 🔒 | L11: 3600 | M11: Накладные ресницы | N11: =IFERROR(__xludf.DUMMYFUNCTION("ArrayFormula(let(category,VLOOKUP($M11, {'📄 Комиссии'!$C:$C , '📄 Комиссии'!$B:$B}, 2, 0), data,MATCH('🔒 Доп. информация'!$J$15:$J203,TRANSPOSE(SPLIT(INDEX('▶️ Инструкция'!$Q:$Q,MATCH($AT11,'▶️ Инструкция'!$R:$R,0)+2),"", "",FALSE)),0), options,COUNTA( "&"ifna( FILTER('🔒 Доп. информация'!$J$15:$J203,('🔒 Доп. информация'!$N$15:$N203=FALSE)*data*('🔒 Доп. информация'!$O$15:$O203=""Опция"")))), commission,VLOOKUP($M11,'📄 Комиссии'!$C:$E,IF($AV11=data!A$8,2,3),0), IF(NOT(ISBLANK($M11)),commission/100+ IFERR"&"OR(VLOOKUP($AT11,{'▶️ Инструкция'!$R:$R,'▶️ Инструкция'!$AK:$AK},2,0)+ IF((( category = ""Одежда"")+( category = ""Обувь"" ))*((options+SUM( ifna( FILTER('🔒 Доп. информация'!$M$15:$M203,('🔒 Доп. информация'!$N$15:$N203=FALSE)*data*('🔒 Доп. информация'!"&"$O$15:$O203=""Пакет"")))))>=5), -5% + 2%, IF((options>=1)* (COUNTA( ifna( FILTER('🔒 Доп. информация'!$J$15:$J203,('🔒 Доп. информация'!$N$15:$N203=FALSE)*data*('🔒 Доп. информация'!$O$15:$O203=""Пакет""))))>=1)* (commission>=14.5)* (category<> ""Одежда"&""")*( category <> ""Обувь"" ),-3% + 2%,0))))))"),0.325) -> 0.325 | O11: =IF($D11,"🔒",) -> 🔒 | Q11: =IF($D11,"🔒",) -> 🔒 | S11: Коледино | T11: Короб | U11: 1 | V11: =IF($D11,"🔒",) -> 🔒 | W11: =IF($D11,"🔒",) -> 🔒 | X11: =IF($D11,"🔒",) -> 🔒 | Y11: =IF($D11,"🔒",) -> 🔒 | Z11: 0 | AA11: =1.7*(1+AJ11)*Z11 -> 0 | AB11: =IF($D11,"🔒",) -> 🔒 | AC11: =IF($D11,"🔒",) -> 🔒 | AD11: =IF($D11,"🔒",) -> 🔒 | AE11: 30 | AF11: 3 | AG11: 16 | AH11: 18 | AI11: =(AF11*AG11*AH11)/1000 -> 0.864 | AJ11: =if(AI11>1,(AI11-1),0) -> 0 | AK11: =IF($D11,"🔒",) -> 🔒 | AL11: {=H11*(1-I11)*VLOOKUP(AT11,{'▶️ Инструкция'!C:C,'▶️ Инструкция'!AI:AI},2,false)} -> 12 | AM11: =IF($D11,"🔒",) -> 🔒 | AN11: 0 | AO11: 0 | AP11: 0 | AQ11: 0.95 | AR11: 0.002 | AS11: 0.01 | AT11: ип Samga | AU11: WB | AV11: FBO | AW11: =AS11*H11 -> 6 | AX11: =(1/(AQ11))*H11*AS11 -> 6.3157895 | AY11: =AX11/BC11 -> 0.043142934 | AZ11: 250 | BA11: =AZ11/H11 -> 0.41666667 | BB11: =H11-AW11 -> 594 | BC11: =BX11 -> 146.39221 | BD11: =BC11*L11 -> 527011.96 | BE11: =H11*(1-I11)*L11 -> 2160000 | BF11: =IFERROR(BC11/BV11,) -> 0.85965407 | BG11: =IFERROR(BC11/H11,) -> 0.24398702 | BH11: =IFERROR(if(BW11>0,BC11/BW11,-BC11/BW11),) -> 0.46226558 | BJ11: =IFERROR(__xludf.DUMMYFUNCTION("IF(AU11=data!A$5, IF(AV11=data!A$8, IF(T11=data!A$3, VLOOKUP(S11,filter('🔒 Доп. информация'!D:H,'🔒 Доп. информация'!C:C=T11),4,FALSE)+VLOOKUP(S11,filter('🔒 Доп. информация'!D:H,'🔒 Доп. информация'!C:C=T11),5,FALSE)*AJ11, IF(AND(MAX(AF11:AH11)<80,SUM(A"&"F11:AH11)<=160,AI11<20,XLOOKUP(M11,'📄 Комиссии'!C:C,'📄 Комиссии'!B:B)<>""Продукты""), VLOOKUP(S11,filter('🔒 Доп. информация'!D:H,'🔒 Доп. информация'!C:C=data!$A$3),4,FALSE)+VLOOKUP(S11,filter('🔒 Доп. информация'!D:H,'🔒 Доп. информация'!C:C=data!$A$3"&"),5,FALSE)*AJ11, VLOOKUP(S11,filter('🔒 Доп. информация'!D:H,'🔒 Доп. информация'!C:C=T11),4,FALSE)*ROUNDUP(AF11*AG11*AH11*L11/(120*80*175))/L11) ) *(AE11/2) ,) ,)*0"),0.0) -> 0 | BK11: =IFERROR(__xludf.DUMMYFUNCTION("IF(AU11=data!A$5, IF(AI11<=1,IF(AI11<=0.8,IF(AI11<=0.6,IF(AI11<=0.4,IF(AI11<=0.2,23,26),29),30),32)*VLOOKUP(S11,filter('🔒 Доп. информация'!D:E,'🔒 Доп. информация'!C:C=T11),2,FALSE)/'🔒 Доп. информация'!$K$9, IF(AV11=data!A$8,U11,1)*VLOOKUP(S11,filter('"&"🔒 Доп. информация'!D:E,'🔒 Доп. информация'!C:C=T11),2,FALSE)+ IF(AV11=data!A$8,U11,1)*VLOOKUP(S11,filter('🔒 Доп. информация'!D:F,'🔒 Доп. информация'!C:C=T11),3,FALSE)*AJ11) ,0)"),64.0) -> 64 | BL11: =IF($D11,"🔒",) -> 🔒 | BM11: =IF($D11,"🔒",) -> 🔒 | BN11: =VLOOKUP(T11,'🔒 Доп. информация'!J:P,7,false) -> 50 | BO11: =IF(AV11=data!A$9, (AA11+AO11+AP11+BJ11+BK11+BN11)+H11*AS11, (BJ11+BK11+BN11)+H11*AS11 ) -> 120 | BP11: =AA11+BJ11+BK11 -> 64 | BQ11: =H11*N11 -> 195 | BR11: =BP11+BQ11+AS11*H11+((1-AQ11)/AQ11)*BO11+AL11+H11*J11*1.1 -> 283.31579 | BS11: {=IF(VLOOKUP(AT11,{'▶️ Инструкция'!C:C,'▶️ Инструкция'!Y:Y},2,FALSE)=data!A$15, H11*(1-I11), (H11-BR11)) *VLOOKUP(AT11,{'▶️ Инструкция'!C:C,'▶️ Инструкция'!AD:AD},2,FALSE)/(1+VLOOKUP(AT11,{'▶️ Инструкция'!C:C,'▶️ Инструкция'!AD:AD},2,FALSE))} -> 0 | BT11: {=IF(VLOOKUP(AT11,{'▶️ Инструкция'!C:C,'▶️ Инструкция'!Y:Y},2,FALSE)=data!A$15, H11*(1-I11)-BS11, (H11-BR11-BS11)) * VLOOKUP(AT11,{'▶️ Инструкция'!C:C,'▶️ Инструкция'!R:R},2,FALSE) +BS11} -> 24 | BU11: =(G11*AR11)+if(AV11=data!A$9,AO11,AN11)+AP11+BR11+BT11 -> 307.60779 | BV11: =(G11*AR11)+if(AV11=data!A$9,AO11,AN11)+AP11+BT11+G11 -> 170.292 | BW11: =H11-BR11 -> 316.68421 | BX11: =BW11-BV11 -> 146.39221
A12: =if(D12=true,if(F12=data!A$1,data!A$10,data!A$11),) | B12: =AV12 -> FBS | C12: Название товара | D12: FALSE | E12: Имя | F12: {=IF(D12=TRUE,IF(IF(BG$3=VLOOKUP(AT12,{'▶️ Инструкция'!C:C,'▶️ Инструкция'!G:G},2,FALSE),BG12,BH12)>VLOOKUP(AT12,{'▶️ Инструкция'!C:C,'▶️ Инструкция'!N:N},2,FALSE),data!A$1,data!A$2),)} | G12: 0 | H12: 1000 | I12: 0 | J12: 0 | K12: =IF($D12,"🔒",) | L12: 0 | M12: Лопатки игрушечные | N12: =IFERROR(__xludf.DUMMYFUNCTION("ArrayFormula(let(category,VLOOKUP($M12, {'📄 Комиссии'!$C:$C , '📄 Комиссии'!$B:$B}, 2, 0), data,MATCH('🔒 Доп. информация'!$J$15:$J203,TRANSPOSE(SPLIT(INDEX('▶️ Инструкция'!$Q:$Q,MATCH($AT12,'▶️ Инструкция'!$R:$R,0)+2),"", "",FALSE)),0), options,COUNTA( "&"ifna( FILTER('🔒 Доп. информация'!$J$15:$J203,('🔒 Доп. информация'!$N$15:$N203=FALSE)*data*('🔒 Доп. информация'!$O$15:$O203=""Опция"")))), commission,VLOOKUP($M12,'📄 Комиссии'!$C:$E,IF($AV12=data!A$8,2,3),0), IF(NOT(ISBLANK($M12)),commission/100+ IFERR"&"OR(VLOOKUP($AT12,{'▶️ Инструкция'!$R:$R,'▶️ Инструкция'!$AK:$AK},2,0)+ IF((( category = ""Одежда"")+( category = ""Обувь"" ))*((options+SUM( ifna( FILTER('🔒 Доп. информация'!$M$15:$M203,('🔒 Доп. информация'!$N$15:$N203=FALSE)*data*('🔒 Доп. информация'!"&"$O$15:$O203=""Пакет"")))))>=5), -5% + 2%, IF((options>=1)* (COUNTA( ifna( FILTER('🔒 Доп. информация'!$J$15:$J203,('🔒 Доп. информация'!$N$15:$N203=FALSE)*data*('🔒 Доп. информация'!$O$15:$O203=""Пакет""))))>=1)* (commission>=14.5)* (category<> ""Одежда"&""")*( category <> ""Обувь"" ),-3% + 2%,0))))))"),0.32) -> 0.32 | O12: =IF($D12,"🔒",) | Q12: =IF($D12,"🔒",) | S12: Макс. из наших | T12: Короб | U12: 1 | V12: =IF($D12,"🔒",) | W12: =IF($D12,"🔒",) | X12: =IF($D12,"🔒",) | Y12: =IF($D12,"🔒",) | Z12: 0 | AA12: =1.7*(1+AJ12)*Z12 -> 0 | AB12: =IF($D12,"🔒",) | AC12: =IF($D12,"🔒",) | AD12: =IF($D12,"🔒",) | AE12: 30 | AF12: 0 | AG12: 0 | AH12: 0 | AI12: =(AF12*AG12*AH12)/1000 -> 0 | AJ12: =if(AI12>1,(AI12-1),0) -> 0 | AK12: =IF($D12,"🔒",) | AL12: {=H12*(1-I12)*VLOOKUP(AT12,{'▶️ Инструкция'!C:C,'▶️ Инструкция'!AI:AI},2,false)} -> #N/A | AM12: =IF($D12,"🔒",) | AN12: 0 | AO12: 0 | AP12: 0 | AQ12: 1 | AR12: 0 | AS12: 0 | AT12: 2 Бренд | AU12: WB | AV12: FBS | AW12: =AS12*H12 -> 0 | AX12: =(1/(AQ12))*H12*AS12 -> 0 | AY12: =AX12/BC12 -> #N/A | AZ12: 250 | BA12: =AZ12/H12 -> 0.25 | BB12: =H12-AW12 -> 1000 | BC12: =BX12 -> #N/A | BD12: =BC12*L12 -> #N/A | BE12: =H12*(1-I12)*L12 -> 0 | BF12: =IFERROR(BC12/BV12,) | BG12: =IFERROR(BC12/H12,) | BH12: =IFERROR(if(BW12>0,BC12/BW12,-BC12/BW12),) | BJ12: =IFERROR(__xludf.DUMMYFUNCTION("IF(AU12=data!A$5, IF(AV12=data!A$8, IF(T12=data!A$3, VLOOKUP(S12,filter('🔒 Доп. информация'!D:H,'🔒 Доп. информация'!C:C=T12),4,FALSE)+VLOOKUP(S12,filter('🔒 Доп. информация'!D:H,'🔒 Доп. информация'!C:C=T12),5,FALSE)*AJ12, IF(AND(MAX(AF12:AH12)<80,SUM(A"&"F12:AH12)<=160,AI12<20,XLOOKUP(M12,'📄 Комиссии'!C:C,'📄 Комиссии'!B:B)<>""Продукты""), VLOOKUP(S12,filter('🔒 Доп. информация'!D:H,'🔒 Доп. информация'!C:C=data!$A$3),4,FALSE)+VLOOKUP(S12,filter('🔒 Доп. информация'!D:H,'🔒 Доп. информация'!C:C=data!$A$3"&"),5,FALSE)*AJ12, VLOOKUP(S12,filter('🔒 Доп. информация'!D:H,'🔒 Доп. информация'!C:C=T12),4,FALSE)*ROUNDUP(AF12*AG12*AH12*L12/(120*80*175))/L12) ) *(AE12/2) ,) ,)*0"),0.0) -> 0 | BK12: =IFERROR(__xludf.DUMMYFUNCTION("IF(AU12=data!A$5, IF(AI12<=1,IF(AI12<=0.8,IF(AI12<=0.6,IF(AI12<=0.4,IF(AI12<=0.2,23,26),29),30),32)*VLOOKUP(S12,filter('🔒 Доп. информация'!D:E,'🔒 Доп. информация'!C:C=T12),2,FALSE)/'🔒 Доп. информация'!$K$9, IF(AV12=data!A$8,U12,1)*VLOOKUP(S12,filter('"&"🔒 Доп. информация'!D:E,'🔒 Доп. информация'!C:C=T12),2,FALSE)+ IF(AV12=data!A$8,U12,1)*VLOOKUP(S12,filter('🔒 Доп. информация'!D:F,'🔒 Доп. информация'!C:C=T12),3,FALSE)*AJ12) ,0)"),69.0) -> 69 | BL12: =IF($D12,"🔒",) | BM12: =IF($D12,"🔒",) | BN12: =VLOOKUP(T12,'🔒 Доп. информация'!J:P,7,false) -> 50 | BO12: =IF(AV12=data!A$9, (AA12+AO12+AP12+BJ12+BK12+BN12)+H12*AS12, (BJ12+BK12+BN12)+H12*AS12 ) -> 119 | BP12: =AA12+BJ12+BK12 -> 69 | BQ12: =H12*N12 -> 320 | BR12: =BP12+BQ12+AS12*H12+((1-AQ12)/AQ12)*BO12+AL12+H12*J12*1.1 -> #N/A | BS12: {=IF(VLOOKUP(AT12,{'▶️ Инструкция'!C:C,'▶️ Инструкция'!Y:Y},2,FALSE)=data!A$15, H12*(1-I12), (H12-BR12)) *VLOOKUP(AT12,{'▶️ Инструкция'!C:C,'▶️ Инструкция'!AD:AD},2,FALSE)/(1+VLOOKUP(AT12,{'▶️ Инструкция'!C:C,'▶️ Инструкция'!AD:AD},2,FALSE))} -> #N/A | BT12: {=IF(VLOOKUP(AT12,{'▶️ Инструкция'!C:C,'▶️ Инструкция'!Y:Y},2,FALSE)=data!A$15, H12*(1-I12)-BS12, (H12-BR12-BS12)) * VLOOKUP(AT12,{'▶️ Инструкция'!C:C,'▶️ Инструкция'!R:R},2,FALSE) +BS12} -> #N/A | BU12: =(G12*AR12)+if(AV12=data!A$9,AO12,AN12)+AP12+BR12+BT12 -> #N/A | BV12: =(G12*AR12)+if(AV12=data!A$9,AO12,AN12)+AP12+BT12+G12 -> #N/A | BW12: =H12-BR12 -> #N/A | BX12: =BW12-BV12 -> #N/A
A13: =if(D13=true,if(F13=data!A$1,data!A$10,data!A$11),) | B13: =AV13 -> FBS | C13: Название товара | D13: FALSE | E13: Имя | F13: {=IF(D13=TRUE,IF(IF(BG$3=VLOOKUP(AT13,{'▶️ Инструкция'!C:C,'▶️ Инструкция'!G:G},2,FALSE),BG13,BH13)>VLOOKUP(AT13,{'▶️ Инструкция'!C:C,'▶️ Инструкция'!N:N},2,FALSE),data!A$1,data!A$2),)} | G13: 0 | H13: 1000 | I13: 0 | J13: 0 | K13: =IF($D13,"🔒",) | L13: 0 | M13: Лопатки игрушечные | N13: =IFERROR(__xludf.DUMMYFUNCTION("ArrayFormula(let(category,VLOOKUP($M13, {'📄 Комиссии'!$C:$C , '📄 Комиссии'!$B:$B}, 2, 0), data,MATCH('🔒 Доп. информация'!$J$15:$J203,TRANSPOSE(SPLIT(INDEX('▶️ Инструкция'!$Q:$Q,MATCH($AT13,'▶️ Инструкция'!$R:$R,0)+2),"", "",FALSE)),0), options,COUNTA( "&"ifna( FILTER('🔒 Доп. информация'!$J$15:$J203,('🔒 Доп. информация'!$N$15:$N203=FALSE)*data*('🔒 Доп. информация'!$O$15:$O203=""Опция"")))), commission,VLOOKUP($M13,'📄 Комиссии'!$C:$E,IF($AV13=data!A$8,2,3),0), IF(NOT(ISBLANK($M13)),commission/100+ IFERR"&"OR(VLOOKUP($AT13,{'▶️ Инструкция'!$R:$R,'▶️ Инструкция'!$AK:$AK},2,0)+ IF((( category = ""Одежда"")+( category = ""Обувь"" ))*((options+SUM( ifna( FILTER('🔒 Доп. информация'!$M$15:$M203,('🔒 Доп. информация'!$N$15:$N203=FALSE)*data*('🔒 Доп. информация'!"&"$O$15:$O203=""Пакет"")))))>=5), -5% + 2%, IF((options>=1)* (COUNTA( ifna( FILTER('🔒 Доп. информация'!$J$15:$J203,('🔒 Доп. информация'!$N$15:$N203=FALSE)*data*('🔒 Доп. информация'!$O$15:$O203=""Пакет""))))>=1)* (commission>=14.5)* (category<> ""Одежда"&""")*( category <> ""Обувь"" ),-3% + 2%,0))))))"),0.32) -> 0.32 | O13: =IF($D13,"🔒",) | Q13: =IF($D13,"🔒",) | S13: Макс. из наших | T13: Короб | U13: 1 | V13: =IF($D13,"🔒",) | W13: =IF($D13,"🔒",) | X13: =IF($D13,"🔒",) | Y13: =IF($D13,"🔒",) | Z13: 0 | AA13: =1.7*(1+AJ13)*Z13 -> 0 | AB13: =IF($D13,"🔒",) | AC13: =IF($D13,"🔒",) | AD13: =IF($D13,"🔒",) | AE13: 30 | AF13: 0 | AG13: 0 | AH13: 0 | AI13: =(AF13*AG13*AH13)/1000 -> 0 | AJ13: =if(AI13>1,(AI13-1),0) -> 0 | AK13: =IF($D13,"🔒",) | AL13: {=H13*(1-I13)*VLOOKUP(AT13,{'▶️ Инструкция'!C:C,'▶️ Инструкция'!AI:AI},2,false)} -> #N/A | AM13: =IF($D13,"🔒",) | AN13: 0 | AO13: 0 | AP13: 0 | AQ13: 1 | AR13: 0 | AS13: 0 | AT13: 2 Бренд | AU13: WB | AV13: FBS | AW13: =AS13*H13 -> 0 | AX13: =(1/(AQ13))*H13*AS13 -> 0 | AY13: =AX13/BC13 -> #N/A | AZ13: 250 | BA13: =AZ13/H13 -> 0.25 | BB13: =H13-AW13 -> 1000 | BC13: =BX13 -> #N/A | BD13: =BC13*L13 -> #N/A | BE13: =H13*(1-I13)*L13 -> 0 | BF13: =IFERROR(BC13/BV13,) | BG13: =IFERROR(BC13/H13,) | BH13: =IFERROR(if(BW13>0,BC13/BW13,-BC13/BW13),) | BJ13: =IFERROR(__xludf.DUMMYFUNCTION("IF(AU13=data!A$5, IF(AV13=data!A$8, IF(T13=data!A$3, VLOOKUP(S13,filter('🔒 Доп. информация'!D:H,'🔒 Доп. информация'!C:C=T13),4,FALSE)+VLOOKUP(S13,filter('🔒 Доп. информация'!D:H,'🔒 Доп. информация'!C:C=T13),5,FALSE)*AJ13, IF(AND(MAX(AF13:AH13)<80,SUM(A"&"F13:AH13)<=160,AI13<20,XLOOKUP(M13,'📄 Комиссии'!C:C,'📄 Комиссии'!B:B)<>""Продукты""), VLOOKUP(S13,filter('🔒 Доп. информация'!D:H,'🔒 Доп. информация'!C:C=data!$A$3),4,FALSE)+VLOOKUP(S13,filter('🔒 Доп. информация'!D:H,'🔒 Доп. информация'!C:C=data!$A$3"&"),5,FALSE)*AJ13, VLOOKUP(S13,filter('🔒 Доп. информация'!D:H,'🔒 Доп. информация'!C:C=T13),4,FALSE)*ROUNDUP(AF13*AG13*AH13*L13/(120*80*175))/L13) ) *(AE13/2) ,) ,)*0"),0.0) -> 0 | BK13: =IFERROR(__xludf.DUMMYFUNCTION("IF(AU13=data!A$5, IF(AI13<=1,IF(AI13<=0.8,IF(AI13<=0.6,IF(AI13<=0.4,IF(AI13<=0.2,23,26),29),30),32)*VLOOKUP(S13,filter('🔒 Доп. информация'!D:E,'🔒 Доп. информация'!C:C=T13),2,FALSE)/'🔒 Доп. информация'!$K$9, IF(AV13=data!A$8,U13,1)*VLOOKUP(S13,filter('"&"🔒 Доп. информация'!D:E,'🔒 Доп. информация'!C:C=T13),2,FALSE)+ IF(AV13=data!A$8,U13,1)*VLOOKUP(S13,filter('🔒 Доп. информация'!D:F,'🔒 Доп. информация'!C:C=T13),3,FALSE)*AJ13) ,0)"),69.0) -> 69 | BL13: =IF($D13,"🔒",) | BM13: =IF($D13,"🔒",) | BN13: =VLOOKUP(T13,'🔒 Доп. информация'!J:P,7,false) -> 50 | BO13: =IF(AV13=data!A$9, (AA13+AO13+AP13+BJ13+BK13+BN13)+H13*AS13, (BJ13+BK13+BN13)+H13*AS13 ) -> 119 | BP13: =AA13+BJ13+BK13 -> 69 | BQ13: =H13*N13 -> 320 | BR13: =BP13+BQ13+AS13*H13+((1-AQ13)/AQ13)*BO13+AL13+H13*J13*1.1 -> #N/A | BS13: {=IF(VLOOKUP(AT13,{'▶️ Инструкция'!C:C,'▶️ Инструкция'!Y:Y},2,FALSE)=data!A$15, H13*(1-I13), (H13-BR13)) *VLOOKUP(AT13,{'▶️ Инструкция'!C:C,'▶️ Инструкция'!AD:AD},2,FALSE)/(1+VLOOKUP(AT13,{'▶️ Инструкция'!C:C,'▶️ Инструкция'!AD:AD},2,FALSE))} -> #N/A | BT13: {=IF(VLOOKUP(AT13,{'▶️ Инструкция'!C:C,'▶️ Инструкция'!Y:Y},2,FALSE)=data!A$15, H13*(1-I13)-BS13, (H13-BR13-BS13)) * VLOOKUP(AT13,{'▶️ Инструкция'!C:C,'▶️ Инструкция'!R:R},2,FALSE) +BS13} -> #N/A | BU13: =(G13*AR13)+if(AV13=data!A$9,AO13,AN13)+AP13+BR13+BT13 -> #N/A | BV13: =(G13*AR13)+if(AV13=data!A$9,AO13,AN13)+AP13+BT13+G13 -> #N/A | BW13: =H13-BR13 -> #N/A | BX13: =BW13-BV13 -> #N/A
A14: =if(D14=true,if(F14=data!A$1,data!A$10,data!A$11),) | B14: =AV14 -> FBS | C14: Название товара | D14: FALSE | E14: Имя | F14: {=IF(D14=TRUE,IF(IF(BG$3=VLOOKUP(AT14,{'▶️ Инструкция'!C:C,'▶️ Инструкция'!G:G},2,FALSE),BG14,BH14)>VLOOKUP(AT14,{'▶️ Инструкция'!C:C,'▶️ Инструкция'!N:N},2,FALSE),data!A$1,data!A$2),)} | G14: 0 | H14: 1000 | I14: 0 | J14: 0 | K14: =IF($D14,"🔒",) | L14: 0 | M14: Лопатки игрушечные | N14: =IFERROR(__xludf.DUMMYFUNCTION("ArrayFormula(let(category,VLOOKUP($M14, {'📄 Комиссии'!$C:$C , '📄 Комиссии'!$B:$B}, 2, 0), data,MATCH('🔒 Доп. информация'!$J$15:$J203,TRANSPOSE(SPLIT(INDEX('▶️ Инструкция'!$Q:$Q,MATCH($AT14,'▶️ Инструкция'!$R:$R,0)+2),"", "",FALSE)),0), options,COUNTA( "&"ifna( FILTER('🔒 Доп. информация'!$J$15:$J203,('🔒 Доп. информация'!$N$15:$N203=FALSE)*data*('🔒 Доп. информация'!$O$15:$O203=""Опция"")))), commission,VLOOKUP($M14,'📄 Комиссии'!$C:$E,IF($AV14=data!A$8,2,3),0), IF(NOT(ISBLANK($M14)),commission/100+ IFERR"&"OR(VLOOKUP($AT14,{'▶️ Инструкция'!$R:$R,'▶️ Инструкция'!$AK:$AK},2,0)+ IF((( category = ""Одежда"")+( category = ""Обувь"" ))*((options+SUM( ifna( FILTER('🔒 Доп. информация'!$M$15:$M203,('🔒 Доп. информация'!$N$15:$N203=FALSE)*data*('🔒 Доп. информация'!"&"$O$15:$O203=""Пакет"")))))>=5), -5% + 2%, IF((options>=1)* (COUNTA( ifna( FILTER('🔒 Доп. информация'!$J$15:$J203,('🔒 Доп. информация'!$N$15:$N203=FALSE)*data*('🔒 Доп. информация'!$O$15:$O203=""Пакет""))))>=1)* (commission>=14.5)* (category<> ""Одежда"&""")*( category <> ""Обувь"" ),-3% + 2%,0))))))"),0.32) -> 0.32 | O14: =IF($D14,"🔒",) | Q14: =IF($D14,"🔒",) | S14: Макс. из наших | T14: Короб | U14: 1 | V14: =IF($D14,"🔒",) | W14: =IF($D14,"🔒",) | X14: =IF($D14,"🔒",) | Y14: =IF($D14,"🔒",) | Z14: 0 | AA14: =1.7*(1+AJ14)*Z14 -> 0 | AB14: =IF($D14,"🔒",) | AC14: =IF($D14,"🔒",) | AD14: =IF($D14,"🔒",) | AE14: 30 | AF14: 0 | AG14: 0 | AH14: 0 | AI14: =(AF14*AG14*AH14)/1000 -> 0 | AJ14: =if(AI14>1,(AI14-1),0) -> 0 | AK14: =IF($D14,"🔒",) | AL14: {=H14*(1-I14)*VLOOKUP(AT14,{'▶️ Инструкция'!C:C,'▶️ Инструкция'!AI:AI},2,false)} -> #N/A | AM14: =IF($D14,"🔒",) | AN14: 0 | AO14: 0 | AP14: 0 | AQ14: 1 | AR14: 0 | AS14: 0 | AT14: 2 Бренд | AU14: WB | AV14: FBS | AW14: =AS14*H14 -> 0 | AX14: =(1/(AQ14))*H14*AS14 -> 0 | AY14: =AX14/BC14 -> #N/A | AZ14: 250 | BA14: =AZ14/H14 -> 0.25 | BB14: =H14-AW14 -> 1000 | BC14: =BX14 -> #N/A | BD14: =BC14*L14 -> #N/A | BE14: =H14*(1-I14)*L14 -> 0 | BF14: =IFERROR(BC14/BV14,) | BG14: =IFERROR(BC14/H14,) | BH14: =IFERROR(if(BW14>0,BC14/BW14,-BC14/BW14),) | BJ14: =IFERROR(__xludf.DUMMYFUNCTION("IF(AU14=data!A$5, IF(AV14=data!A$8, IF(T14=data!A$3, VLOOKUP(S14,filter('🔒 Доп. информация'!D:H,'🔒 Доп. информация'!C:C=T14),4,FALSE)+VLOOKUP(S14,filter('🔒 Доп. информация'!D:H,'🔒 Доп. информация'!C:C=T14),5,FALSE)*AJ14, IF(AND(MAX(AF14:AH14)<80,SUM(A"&"F14:AH14)<=160,AI14<20,XLOOKUP(M14,'📄 Комиссии'!C:C,'📄 Комиссии'!B:B)<>""Продукты""), VLOOKUP(S14,filter('🔒 Доп. информация'!D:H,'🔒 Доп. информация'!C:C=data!$A$3),4,FALSE)+VLOOKUP(S14,filter('🔒 Доп. информация'!D:H,'🔒 Доп. информация'!C:C=data!$A$3"&"),5,FALSE)*AJ14, VLOOKUP(S14,filter('🔒 Доп. информация'!D:H,'🔒 Доп. информация'!C:C=T14),4,FALSE)*ROUNDUP(AF14*AG14*AH14*L14/(120*80*175))/L14) ) *(AE14/2) ,) ,)*0"),0.0) -> 0 | BK14: =IFERROR(__xludf.DUMMYFUNCTION("IF(AU14=data!A$5, IF(AI14<=1,IF(AI14<=0.8,IF(AI14<=0.6,IF(AI14<=0.4,IF(AI14<=0.2,23,26),29),30),32)*VLOOKUP(S14,filter('🔒 Доп. информация'!D:E,'🔒 Доп. информация'!C:C=T14),2,FALSE)/'🔒 Доп. информация'!$K$9, IF(AV14=data!A$8,U14,1)*VLOOKUP(S14,filter('"&"🔒 Доп. информация'!D:E,'🔒 Доп. информация'!C:C=T14),2,FALSE)+ IF(AV14=data!A$8,U14,1)*VLOOKUP(S14,filter('🔒 Доп. информация'!D:F,'🔒 Доп. информация'!C:C=T14),3,FALSE)*AJ14) ,0)"),69.0) -> 69 | BL14: =IF($D14,"🔒",) | BM14: =IF($D14,"🔒",) | BN14: =VLOOKUP(T14,'🔒 Доп. информация'!J:P,7,false) -> 50 | BO14: =IF(AV14=data!A$9, (AA14+AO14+AP14+BJ14+BK14+BN14)+H14*AS14, (BJ14+BK14+BN14)+H14*AS14 ) -> 119 | BP14: =AA14+BJ14+BK14 -> 69 | BQ14: =H14*N14 -> 320 | BR14: =BP14+BQ14+AS14*H14+((1-AQ14)/AQ14)*BO14+AL14+H14*J14*1.1 -> #N/A | BS14: {=IF(VLOOKUP(AT14,{'▶️ Инструкция'!C:C,'▶️ Инструкция'!Y:Y},2,FALSE)=data!A$15, H14*(1-I14), (H14-BR14)) *VLOOKUP(AT14,{'▶️ Инструкция'!C:C,'▶️ Инструкция'!AD:AD},2,FALSE)/(1+VLOOKUP(AT14,{'▶️ Инструкция'!C:C,'▶️ Инструкция'!AD:AD},2,FALSE))} -> #N/A | BT14: {=IF(VLOOKUP(AT14,{'▶️ Инструкция'!C:C,'▶️ Инструкция'!Y:Y},2,FALSE)=data!A$15, H14*(1-I14)-BS14, (H14-BR14-BS14)) * VLOOKUP(AT14,{'▶️ Инструкция'!C:C,'▶️ Инструкция'!R:R},2,FALSE) +BS14} -> #N/A | BU14: =(G14*AR14)+if(AV14=data!A$9,AO14,AN14)+AP14+BR14+BT14 -> #N/A | BV14: =(G14*AR14)+if(AV14=data!A$9,AO14,AN14)+AP14+BT14+G14 -> #N/A | BW14: =H14-BR14 -> #N/A | BX14: =BW14-BV14 -> #N/A
A15: =if(D15=true,if(F15=data!A$1,data!A$10,data!A$11),) | B15: =AV15 -> FBS | C15: Название товара | D15: FALSE | E15: Имя | F15: {=IF(D15=TRUE,IF(IF(BG$3=VLOOKUP(AT15,{'▶️ Инструкция'!C:C,'▶️ Инструкция'!G:G},2,FALSE),BG15,BH15)>VLOOKUP(AT15,{'▶️ Инструкция'!C:C,'▶️ Инструкция'!N:N},2,FALSE),data!A$1,data!A$2),)} | G15: 0 | H15: 1000 | I15: 0 | J15: 0 | K15: =IF($D15,"🔒",) | L15: 0 | M15: Лопатки игрушечные | N15: =IFERROR(__xludf.DUMMYFUNCTION("ArrayFormula(let(category,VLOOKUP($M15, {'📄 Комиссии'!$C:$C , '📄 Комиссии'!$B:$B}, 2, 0), data,MATCH('🔒 Доп. информация'!$J$15:$J203,TRANSPOSE(SPLIT(INDEX('▶️ Инструкция'!$Q:$Q,MATCH($AT15,'▶️ Инструкция'!$R:$R,0)+2),"", "",FALSE)),0), options,COUNTA( "&"ifna( FILTER('🔒 Доп. информация'!$J$15:$J203,('🔒 Доп. информация'!$N$15:$N203=FALSE)*data*('🔒 Доп. информация'!$O$15:$O203=""Опция"")))), commission,VLOOKUP($M15,'📄 Комиссии'!$C:$E,IF($AV15=data!A$8,2,3),0), IF(NOT(ISBLANK($M15)),commission/100+ IFERR"&"OR(VLOOKUP($AT15,{'▶️ Инструкция'!$R:$R,'▶️ Инструкция'!$AK:$AK},2,0)+ IF((( category = ""Одежда"")+( category = ""Обувь"" ))*((options+SUM( ifna( FILTER('🔒 Доп. информация'!$M$15:$M203,('🔒 Доп. информация'!$N$15:$N203=FALSE)*data*('🔒 Доп. информация'!"&"$O$15:$O203=""Пакет"")))))>=5), -5% + 2%, IF((options>=1)* (COUNTA( ifna( FILTER('🔒 Доп. информация'!$J$15:$J203,('🔒 Доп. информация'!$N$15:$N203=FALSE)*data*('🔒 Доп. информация'!$O$15:$O203=""Пакет""))))>=1)* (commission>=14.5)* (category<> ""Одежда"&""")*( category <> ""Обувь"" ),-3% + 2%,0))))))"),0.32) -> 0.32 | O15: =IF($D15,"🔒",) | Q15: =IF($D15,"🔒",) | S15: Макс. из наших | T15: Короб | U15: 1 | V15: =IF($D15,"🔒",) | W15: =IF($D15,"🔒",) | X15: =IF($D15,"🔒",) | Y15: =IF($D15,"🔒",) | Z15: 0 | AA15: =1.7*(1+AJ15)*Z15 -> 0 | AB15: =IF($D15,"🔒",) | AC15: =IF($D15,"🔒",) | AD15: =IF($D15,"🔒",) | AE15: 30 | AF15: 0 | AG15: 0 | AH15: 0 | AI15: =(AF15*AG15*AH15)/1000 -> 0 | AJ15: =if(AI15>1,(AI15-1),0) -> 0 | AK15: =IF($D15,"🔒",) | AL15: {=H15*(1-I15)*VLOOKUP(AT15,{'▶️ Инструкция'!C:C,'▶️ Инструкция'!AI:AI},2,false)} -> #N/A | AM15: =IF($D15,"🔒",) | AN15: 0 | AO15: 0 | AP15: 0 | AQ15: 1 | AR15: 0 | AS15: 0 | AT15: ИП Иванов И.И. | AU15: WB | AV15: FBS | AW15: =AS15*H15 -> 0 | AX15: =(1/(AQ15))*H15*AS15 -> 0 | AY15: =AX15/BC15 -> #N/A | AZ15: 250 | BA15: =AZ15/H15 -> 0.25 | BB15: =H15-AW15 -> 1000 | BC15: =BX15 -> #N/A | BD15: =BC15*L15 -> #N/A | BE15: =H15*(1-I15)*L15 -> 0 | BF15: =IFERROR(BC15/BV15,) | BG15: =IFERROR(BC15/H15,) | BH15: =IFERROR(if(BW15>0,BC15/BW15,-BC15/BW15),) | BJ15: =IFERROR(__xludf.DUMMYFUNCTION("IF(AU15=data!A$5, IF(AV15=data!A$8, IF(T15=data!A$3, VLOOKUP(S15,filter('🔒 Доп. информация'!D:H,'🔒 Доп. информация'!C:C=T15),4,FALSE)+VLOOKUP(S15,filter('🔒 Доп. информация'!D:H,'🔒 Доп. информация'!C:C=T15),5,FALSE)*AJ15, IF(AND(MAX(AF15:AH15)<80,SUM(A"&"F15:AH15)<=160,AI15<20,XLOOKUP(M15,'📄 Комиссии'!C:C,'📄 Комиссии'!B:B)<>""Продукты""), VLOOKUP(S15,filter('🔒 Доп. информация'!D:H,'🔒 Доп. информация'!C:C=data!$A$3),4,FALSE)+VLOOKUP(S15,filter('🔒 Доп. информация'!D:H,'🔒 Доп. информация'!C:C=data!$A$3"&"),5,FALSE)*AJ15, VLOOKUP(S15,filter('🔒 Доп. информация'!D:H,'🔒 Доп. информация'!C:C=T15),4,FALSE)*ROUNDUP(AF15*AG15*AH15*L15/(120*80*175))/L15) ) *(AE15/2) ,) ,)*0"),0.0) -> 0 | BK15: =IFERROR(__xludf.DUMMYFUNCTION("IF(AU15=data!A$5, IF(AI15<=1,IF(AI15<=0.8,IF(AI15<=0.6,IF(AI15<=0.4,IF(AI15<=0.2,23,26),29),30),32)*VLOOKUP(S15,filter('🔒 Доп. информация'!D:E,'🔒 Доп. информация'!C:C=T15),2,FALSE)/'🔒 Доп. информация'!$K$9, IF(AV15=data!A$8,U15,1)*VLOOKUP(S15,filter('"&"🔒 Доп. информация'!D:E,'🔒 Доп. информация'!C:C=T15),2,FALSE)+ IF(AV15=data!A$8,U15,1)*VLOOKUP(S15,filter('🔒 Доп. информация'!D:F,'🔒 Доп. информация'!C:C=T15),3,FALSE)*AJ15) ,0)"),69.0) -> 69 | BL15: =IF($D15,"🔒",) | BM15: =IF($D15,"🔒",) | BN15: =VLOOKUP(T15,'🔒 Доп. информация'!J:P,7,false) -> 50 | BO15: =IF(AV15=data!A$9, (AA15+AO15+AP15+BJ15+BK15+BN15)+H15*AS15, (BJ15+BK15+BN15)+H15*AS15 ) -> 119 | BP15: =AA15+BJ15+BK15 -> 69 | BQ15: =H15*N15 -> 320 | BR15: =BP15+BQ15+AS15*H15+((1-AQ15)/AQ15)*BO15+AL15+H15*J15*1.1 -> #N/A | BS15: {=IF(VLOOKUP(AT15,{'▶️ Инструкция'!C:C,'▶️ Инструкция'!Y:Y},2,FALSE)=data!A$15, H15*(1-I15), (H15-BR15)) *VLOOKUP(AT15,{'▶️ Инструкция'!C:C,'▶️ Инструкция'!AD:AD},2,FALSE)/(1+VLOOKUP(AT15,{'▶️ Инструкция'!C:C,'▶️ Инструкция'!AD:AD},2,FALSE))} -> #N/A | BT15: {=IF(VLOOKUP(AT15,{'▶️ Инструкция'!C:C,'▶️ Инструкция'!Y:Y},2,FALSE)=data!A$15, H15*(1-I15)-BS15, (H15-BR15-BS15)) * VLOOKUP(AT15,{'▶️ Инструкция'!C:C,'▶️ Инструкция'!R:R},2,FALSE) +BS15} -> #N/A | BU15: =(G15*AR15)+if(AV15=data!A$9,AO15,AN15)+AP15+BR15+BT15 -> #N/A | BV15: =(G15*AR15)+if(AV15=data!A$9,AO15,AN15)+AP15+BT15+G15 -> #N/A | BW15: =H15-BR15 -> #N/A | BX15: =BW15-BV15 -> #N/A
